<robot name = "robot">
    <link name="Torso">
        <inertial>
            <origin xyz="0 0 0.7794645440129542" rpy="0 0 0"/>
            <mass value="1" />
            <inertia ixx="100" ixy="0" ixz="0" iyy="100" iyz="0" izz="100" />
        </inertial>
        <visual>
            <origin xyz="0 0 0.7794645440129542" rpy="0 0 0"/>
            <geometry>
                <box size="1.4266648176813996 2.6712573604426346 1.5589290880259083" />
            </geometry>
            <material name="Cyan">
                <color rgba="0 1.0 1.0 1.0"/>
            </material>
        </visual>
        <collision>
            <origin xyz="0 0 0.7794645440129542" rpy="0 0 0"/>
            <geometry>
                <box size="1.4266648176813996 2.6712573604426346 1.5589290880259083" />
            </geometry>
        </collision>
    </link>
    <joint name="Torso_BL" type="revolute">
       <parent link="Torso"/>
       <child  link="BL"/>
       <origin rpy="0 0 0" xyz="0 -0.5 1" />
     <axis xyz="1 0 0"/>
       <limit effort="0.0" lower="-3.14159" upper="3.14159" velocity="0.0"/>
    </joint>
    <link name="BL">
        <inertial>
            <origin xyz="0 -2.793383820510521 0" rpy="0 0 0"/>
            <mass value="1" />
            <inertia ixx="100" ixy="0" ixz="0" iyy="100" iyz="0" izz="100" />
        </inertial>
        <visual>
            <origin xyz="0 -2.793383820510521 0" rpy="0 0 0"/>
            <geometry>
                <box size="1.1347780757924513 2.915510280578407 2.3706562108400258" />
            </geometry>
            <material name="Cyan">
                <color rgba="0 1.0 1.0 1.0"/>
            </material>
        </visual>
        <collision>
            <origin xyz="0 -2.793383820510521 0" rpy="0 0 0"/>
            <geometry>
                <box size="1.1347780757924513 2.915510280578407 2.3706562108400258" />
            </geometry>
        </collision>
    </link>
</robot>