<robot name = "robot">
    <link name="0">
        <inertial>
            <origin xyz="0 0 1.726544088786739" rpy="0 0 0"/>
            <mass value="1" />
            <inertia ixx="100" ixy="0" ixz="0" iyy="100" iyz="0" izz="100" />
        </inertial>
        <visual>
            <origin xyz="0 0 1.726544088786739" rpy="0 0 0"/>
            <geometry>
                <box size="1.671956454300183 0.8462512511730396 0.45308817757347764" />
            </geometry>
            <material name="Green">
                <color rgba="0 1.0 0.0 1.0"/>
            </material>
        </visual>
        <collision>
            <origin xyz="0 0 1.726544088786739" rpy="0 0 0"/>
            <geometry>
                <box size="1.671956454300183 0.8462512511730396 0.45308817757347764" />
            </geometry>
        </collision>
    </link>
    <joint name="0_Head" type="revolute">
       <parent link="0"/>
       <child  link="Head"/>
       <origin rpy="0 0 0" xyz="-0.8359782271500915 0 1.726544088786739" />
     <axis xyz="0 1 0"/>
       <limit effort="0.0" lower="-3.14159" upper="3.14159" velocity="0.0"/>
    </joint>
    <link name="Head">
        <inertial>
            <origin xyz="-0.10449727839376144 0 0.45308817757347764" rpy="0 0 0"/>
            <mass value="1" />
            <inertia ixx="100" ixy="0" ixz="0" iyy="100" iyz="0" izz="100" />
        </inertial>
        <visual>
            <origin xyz="-0.10449727839376144 0 0.45308817757347764" rpy="0 0 0"/>
            <geometry>
                <box size="0.41798911357504576 0.4231256255865198 0.45308817757347764" />
            </geometry>
            <material name="Blue">
                <color rgba="0.0 0.0 1.0 1.0"/>
            </material>
        </visual>
        <collision>
            <origin xyz="-0.10449727839376144 0 0.45308817757347764" rpy="0 0 0"/>
            <geometry>
                <box size="0.41798911357504576 0.4231256255865198 0.45308817757347764" />
            </geometry>
        </collision>
    </link>
</robot>