<robot name = "robot">
    <link name="0">
        <inertial>
            <origin xyz="0 0 0.22888958282013575" rpy="0 0 0"/>
            <mass value="1" />
            <inertia ixx="100" ixy="0" ixz="0" iyy="100" iyz="0" izz="100" />
        </inertial>
        <visual>
            <origin xyz="0 0 0.22888958282013575" rpy="0 0 0"/>
            <geometry>
                <box size="1.604453860444328 0.7299119179762191 0.4577791656402715" />
            </geometry>
            <material name="Blue">
                <color rgba="0 0.0 1.0 1.0"/>
            </material>
        </visual>
        <collision>
            <origin xyz="0 0 0.22888958282013575" rpy="0 0 0"/>
            <geometry>
                <box size="1.604453860444328 0.7299119179762191 0.4577791656402715" />
            </geometry>
        </collision>
    </link>
    <joint name="0_Head" type="revolute">
       <parent link="0"/>
       <child  link="Head"/>
       <origin rpy="0 0 0" xyz="-0.802226930222164 0 0.22888958282013575" />
     <axis xyz="0 1 0"/>
       <limit effort="0.0" lower="-3.14159" upper="3.14159" velocity="0.0"/>
    </joint>
    <link name="Head">
        <inertial>
            <origin xyz="-0.1002783662777705 0 0.34333437423020363" rpy="0 0 0"/>
            <mass value="1" />
            <inertia ixx="100" ixy="0" ixz="0" iyy="100" iyz="0" izz="100" />
        </inertial>
        <visual>
            <origin xyz="-0.1002783662777705 0 0.34333437423020363" rpy="0 0 0"/>
            <geometry>
                <box size="0.401113465111082 0.36495595898810956 0.34333437423020363" />
            </geometry>
            <material name="Cyan">
                <color rgba="0.0 1.0 1.0 1.0"/>
            </material>
        </visual>
        <collision>
            <origin xyz="-0.1002783662777705 0 0.34333437423020363" rpy="0 0 0"/>
            <geometry>
                <box size="0.401113465111082 0.36495595898810956 0.34333437423020363" />
            </geometry>
        </collision>
    </link>
    <joint name="0_4" type="revolute">
       <parent link="0"/>
       <child  link="4"/>
       <origin rpy="0 0 0" xyz="0.5348179534814427 -0.36495595898810956 0.22888958282013575" />
     <axis xyz="1 0 0"/>
       <limit effort="0.0" lower="-3.14159" upper="3.14159" velocity="0.0"/>
    </joint>
    <link name="4">
        <inertial>
            <origin xyz="0.09174561168172053 -0.35790600666331585 -0.04500957394792493" rpy="0 0 0"/>
            <mass value="1" />
            <inertia ixx="100" ixy="0" ixz="0" iyy="100" iyz="0" izz="100" />
        </inertial>
        <visual>
            <origin xyz="0.09174561168172053 -0.35790600666331585 -0.04500957394792493" rpy="0 0 0"/>
            <geometry>
                <box size="0.18349122336344106 0.7158120133266317 0.09001914789584986" />
            </geometry>
            <material name="Blue">
                <color rgba="0 0.0 1.0 1.0"/>
            </material>
        </visual>
        <collision>
            <origin xyz="0.09174561168172053 -0.35790600666331585 -0.04500957394792493" rpy="0 0 0"/>
            <geometry>
                <box size="0.18349122336344106 0.7158120133266317 0.09001914789584986" />
            </geometry>
        </collision>
    </link>
    <joint name="4_14" type="revolute">
       <parent link="4"/>
       <child  link="14"/>
       <origin rpy="0 0 0" xyz="0.18349122336344106 -0.7158120133266317 -0.04500957394792493" />
     <axis xyz="0 1 0"/>
       <limit effort="0.0" lower="-3.14159" upper="3.14159" velocity="0.0"/>
    </joint>
    <link name="14">
        <inertial>
            <origin xyz="0.16570876776386187 0.18851997288283057 -0.09811354762418023" rpy="0 0 0"/>
            <mass value="1" />
            <inertia ixx="100" ixy="0" ixz="0" iyy="100" iyz="0" izz="100" />
        </inertial>
        <visual>
            <origin xyz="0.16570876776386187 0.18851997288283057 -0.09811354762418023" rpy="0 0 0"/>
            <geometry>
                <box size="0.33141753552772374 0.37703994576566113 0.19622709524836046" />
            </geometry>
            <material name="Green">
                <color rgba="0 1.0 0.0 1.0"/>
            </material>
        </visual>
        <collision>
            <origin xyz="0.16570876776386187 0.18851997288283057 -0.09811354762418023" rpy="0 0 0"/>
            <geometry>
                <box size="0.33141753552772374 0.37703994576566113 0.19622709524836046" />
            </geometry>
        </collision>
    </link>
</robot>