<robot name = "robot">
    <link name="0">
        <inertial>
            <origin xyz="0 0 0.17234741354928979" rpy="0 0 0"/>
            <mass value="1" />
            <inertia ixx="100" ixy="0" ixz="0" iyy="100" iyz="0" izz="100" />
        </inertial>
        <visual>
            <origin xyz="0 0 0.17234741354928979" rpy="0 0 0"/>
            <geometry>
                <box size="1.7653326837309282 0.9330913087447423 0.34469482709857957" />
            </geometry>
            <material name="Blue">
                <color rgba="0 0.0 1.0 1.0"/>
            </material>
        </visual>
        <collision>
            <origin xyz="0 0 0.17234741354928979" rpy="0 0 0"/>
            <geometry>
                <box size="1.7653326837309282 0.9330913087447423 0.34469482709857957" />
            </geometry>
        </collision>
    </link>
    <joint name="0_Head" type="revolute">
       <parent link="0"/>
       <child  link="Head"/>
       <origin rpy="0 0 0" xyz="-0.8826663418654641 0 0.17234741354928979" />
     <axis xyz="0 1 0"/>
       <limit effort="0.0" lower="-3.14159" upper="3.14159" velocity="0.0"/>
    </joint>
    <link name="Head">
        <inertial>
            <origin xyz="-0.11033329273318301 0 0.2585211203239347" rpy="0 0 0"/>
            <mass value="1" />
            <inertia ixx="100" ixy="0" ixz="0" iyy="100" iyz="0" izz="100" />
        </inertial>
        <visual>
            <origin xyz="-0.11033329273318301 0 0.2585211203239347" rpy="0 0 0"/>
            <geometry>
                <box size="0.44133317093273206 0.46654565437237117 0.2585211203239347" />
            </geometry>
            <material name="Cyan">
                <color rgba="0.0 1.0 1.0 1.0"/>
            </material>
        </visual>
        <collision>
            <origin xyz="-0.11033329273318301 0 0.2585211203239347" rpy="0 0 0"/>
            <geometry>
                <box size="0.44133317093273206 0.46654565437237117 0.2585211203239347" />
            </geometry>
        </collision>
    </link>
    <joint name="0_1" type="revolute">
       <parent link="0"/>
       <child  link="1"/>
       <origin rpy="0 0 0" xyz="0.5884442279103094 0.46654565437237117 0.17234741354928979" />
     <axis xyz="1 0 0"/>
       <limit effort="0.0" lower="-3.14159" upper="3.14159" velocity="0.0"/>
    </joint>
    <link name="1">
        <inertial>
            <origin xyz="0.19612568046919837 0.36501761217377193 -0.09578458360863829" rpy="0 0 0"/>
            <mass value="1" />
            <inertia ixx="100" ixy="0" ixz="0" iyy="100" iyz="0" izz="100" />
        </inertial>
        <visual>
            <origin xyz="0.19612568046919837 0.36501761217377193 -0.09578458360863829" rpy="0 0 0"/>
            <geometry>
                <box size="0.39225136093839674 0.7300352243475439 0.19156916721727657" />
            </geometry>
            <material name="Green">
                <color rgba="0 1.0 0.0 1.0"/>
            </material>
        </visual>
        <collision>
            <origin xyz="0.19612568046919837 0.36501761217377193 -0.09578458360863829" rpy="0 0 0"/>
            <geometry>
                <box size="0.39225136093839674 0.7300352243475439 0.19156916721727657" />
            </geometry>
        </collision>
    </link>
    <joint name="1_11" type="revolute">
       <parent link="1"/>
       <child  link="11"/>
       <origin rpy="0 0 0" xyz="0.39225136093839674 0.7300352243475439 -0.09578458360863829" />
     <axis xyz="0 1 0"/>
       <limit effort="0.0" lower="-3.14159" upper="3.14159" velocity="0.0"/>
    </joint>
    <link name="11">
        <inertial>
            <origin xyz="0.48657829250217355 -0.10889165021787477 -0.048319752142656776" rpy="0 0 0"/>
            <mass value="1" />
            <inertia ixx="100" ixy="0" ixz="0" iyy="100" iyz="0" izz="100" />
        </inertial>
        <visual>
            <origin xyz="0.48657829250217355 -0.10889165021787477 -0.048319752142656776" rpy="0 0 0"/>
            <geometry>
                <box size="0.9731565850043471 0.21778330043574953 0.09663950428531355" />
            </geometry>
            <material name="Green">
                <color rgba="0 1.0 0.0 1.0"/>
            </material>
        </visual>
        <collision>
            <origin xyz="0.48657829250217355 -0.10889165021787477 -0.048319752142656776" rpy="0 0 0"/>
            <geometry>
                <box size="0.9731565850043471 0.21778330043574953 0.09663950428531355" />
            </geometry>
        </collision>
    </link>
    <joint name="0_2" type="revolute">
       <parent link="0"/>
       <child  link="2"/>
       <origin rpy="0 0 0" xyz="-0.5884442279103094 0.46654565437237117 0.17234741354928979" />
     <axis xyz="1 0 0"/>
       <limit effort="0.0" lower="-3.14159" upper="3.14159" velocity="0.0"/>
    </joint>
    <link name="2">
        <inertial>
            <origin xyz="-0.14411331280620066 0.3556028073810228 -0.0801049955901238" rpy="0 0 0"/>
            <mass value="1" />
            <inertia ixx="100" ixy="0" ixz="0" iyy="100" iyz="0" izz="100" />
        </inertial>
        <visual>
            <origin xyz="-0.14411331280620066 0.3556028073810228 -0.0801049955901238" rpy="0 0 0"/>
            <geometry>
                <box size="0.2882266256124013 0.7112056147620456 0.1602099911802476" />
            </geometry>
            <material name="Blue">
                <color rgba="0 0.0 1.0 1.0"/>
            </material>
        </visual>
        <collision>
            <origin xyz="-0.14411331280620066 0.3556028073810228 -0.0801049955901238" rpy="0 0 0"/>
            <geometry>
                <box size="0.2882266256124013 0.7112056147620456 0.1602099911802476" />
            </geometry>
        </collision>
    </link>
    <joint name="2_12" type="revolute">
       <parent link="2"/>
       <child  link="12"/>
       <origin rpy="0 0 0" xyz="-0.2882266256124013 0.7112056147620456 -0.0801049955901238" />
     <axis xyz="0 1 0"/>
       <limit effort="0.0" lower="-3.14159" upper="3.14159" velocity="0.0"/>
    </joint>
    <link name="12">
        <inertial>
            <origin xyz="-0.3783283932981635 -0.13602534951564887 -0.051794777320134024" rpy="0 0 0"/>
            <mass value="1" />
            <inertia ixx="100" ixy="0" ixz="0" iyy="100" iyz="0" izz="100" />
        </inertial>
        <visual>
            <origin xyz="-0.3783283932981635 -0.13602534951564887 -0.051794777320134024" rpy="0 0 0"/>
            <geometry>
                <box size="0.756656786596327 0.27205069903129775 0.10358955464026805" />
            </geometry>
            <material name="Green">
                <color rgba="0 1.0 0.0 1.0"/>
            </material>
        </visual>
        <collision>
            <origin xyz="-0.3783283932981635 -0.13602534951564887 -0.051794777320134024" rpy="0 0 0"/>
            <geometry>
                <box size="0.756656786596327 0.27205069903129775 0.10358955464026805" />
            </geometry>
        </collision>
    </link>
    <joint name="0_3" type="revolute">
       <parent link="0"/>
       <child  link="3"/>
       <origin rpy="0 0 0" xyz="-0.5884442279103094 -0.46654565437237117 0.17234741354928979" />
     <axis xyz="1 0 0"/>
       <limit effort="0.0" lower="-3.14159" upper="3.14159" velocity="0.0"/>
    </joint>
    <link name="3">
        <inertial>
            <origin xyz="-0.09658520026983848 -0.35411188927058035 -0.060049351562930946" rpy="0 0 0"/>
            <mass value="1" />
            <inertia ixx="100" ixy="0" ixz="0" iyy="100" iyz="0" izz="100" />
        </inertial>
        <visual>
            <origin xyz="-0.09658520026983848 -0.35411188927058035 -0.060049351562930946" rpy="0 0 0"/>
            <geometry>
                <box size="0.19317040053967696 0.7082237785411607 0.12009870312586189" />
            </geometry>
            <material name="Green">
                <color rgba="0 1.0 0.0 1.0"/>
            </material>
        </visual>
        <collision>
            <origin xyz="-0.09658520026983848 -0.35411188927058035 -0.060049351562930946" rpy="0 0 0"/>
            <geometry>
                <box size="0.19317040053967696 0.7082237785411607 0.12009870312586189" />
            </geometry>
        </collision>
    </link>
    <joint name="3_13" type="revolute">
       <parent link="3"/>
       <child  link="13"/>
       <origin rpy="0 0 0" xyz="-0.19317040053967696 -0.7082237785411607 -0.060049351562930946" />
     <axis xyz="0 1 0"/>
       <limit effort="0.0" lower="-3.14159" upper="3.14159" velocity="0.0"/>
    </joint>
    <link name="13">
        <inertial>
            <origin xyz="-0.38330264057601016 0.13449596992865592 -0.02981547784770451" rpy="0 0 0"/>
            <mass value="1" />
            <inertia ixx="100" ixy="0" ixz="0" iyy="100" iyz="0" izz="100" />
        </inertial>
        <visual>
            <origin xyz="-0.38330264057601016 0.13449596992865592 -0.02981547784770451" rpy="0 0 0"/>
            <geometry>
                <box size="0.7666052811520203 0.26899193985731185 0.05963095569540902" />
            </geometry>
            <material name="Green">
                <color rgba="0 1.0 0.0 1.0"/>
            </material>
        </visual>
        <collision>
            <origin xyz="-0.38330264057601016 0.13449596992865592 -0.02981547784770451" rpy="0 0 0"/>
            <geometry>
                <box size="0.7666052811520203 0.26899193985731185 0.05963095569540902" />
            </geometry>
        </collision>
    </link>
    <joint name="0_4" type="revolute">
       <parent link="0"/>
       <child  link="4"/>
       <origin rpy="0 0 0" xyz="0.5884442279103094 -0.46654565437237117 0.17234741354928979" />
     <axis xyz="1 0 0"/>
       <limit effort="0.0" lower="-3.14159" upper="3.14159" velocity="0.0"/>
    </joint>
    <link name="4">
        <inertial>
            <origin xyz="0.12239117948596423 -0.39577100878917926 -0.08529466386341228" rpy="0 0 0"/>
            <mass value="1" />
            <inertia ixx="100" ixy="0" ixz="0" iyy="100" iyz="0" izz="100" />
        </inertial>
        <visual>
            <origin xyz="0.12239117948596423 -0.39577100878917926 -0.08529466386341228" rpy="0 0 0"/>
            <geometry>
                <box size="0.24478235897192846 0.7915420175783585 0.17058932772682456" />
            </geometry>
            <material name="Blue">
                <color rgba="0 0.0 1.0 1.0"/>
            </material>
        </visual>
        <collision>
            <origin xyz="0.12239117948596423 -0.39577100878917926 -0.08529466386341228" rpy="0 0 0"/>
            <geometry>
                <box size="0.24478235897192846 0.7915420175783585 0.17058932772682456" />
            </geometry>
        </collision>
    </link>
    <joint name="4_14" type="revolute">
       <parent link="4"/>
       <child  link="14"/>
       <origin rpy="0 0 0" xyz="0.24478235897192846 -0.7915420175783585 -0.08529466386341228" />
     <axis xyz="0 1 0"/>
       <limit effort="0.0" lower="-3.14159" upper="3.14159" velocity="0.0"/>
    </joint>
    <link name="14">
        <inertial>
            <origin xyz="0.4254327936846305 0.19929650788052317 -0.08311287407555254" rpy="0 0 0"/>
            <mass value="1" />
            <inertia ixx="100" ixy="0" ixz="0" iyy="100" iyz="0" izz="100" />
        </inertial>
        <visual>
            <origin xyz="0.4254327936846305 0.19929650788052317 -0.08311287407555254" rpy="0 0 0"/>
            <geometry>
                <box size="0.850865587369261 0.39859301576104633 0.16622574815110508" />
            </geometry>
            <material name="Green">
                <color rgba="0 1.0 0.0 1.0"/>
            </material>
        </visual>
        <collision>
            <origin xyz="0.4254327936846305 0.19929650788052317 -0.08311287407555254" rpy="0 0 0"/>
            <geometry>
                <box size="0.850865587369261 0.39859301576104633 0.16622574815110508" />
            </geometry>
        </collision>
    </link>
</robot>