<robot name = "robot">
    <link name="0">
        <inertial>
            <origin xyz="0 0 0.23839568311192308" rpy="0 0 0"/>
            <mass value="1" />
            <inertia ixx="100" ixy="0" ixz="0" iyy="100" iyz="0" izz="100" />
        </inertial>
        <visual>
            <origin xyz="0 0 0.23839568311192308" rpy="0 0 0"/>
            <geometry>
                <box size="1.5990969001439848 0.6947977524868147 0.47679136622384616" />
            </geometry>
            <material name="Blue">
                <color rgba="0 0.0 1.0 1.0"/>
            </material>
        </visual>
        <collision>
            <origin xyz="0 0 0.23839568311192308" rpy="0 0 0"/>
            <geometry>
                <box size="1.5990969001439848 0.6947977524868147 0.47679136622384616" />
            </geometry>
        </collision>
    </link>
    <joint name="0_Head" type="revolute">
       <parent link="0"/>
       <child  link="Head"/>
       <origin rpy="0 0 0" xyz="-0.7995484500719924 0 0.23839568311192308" />
     <axis xyz="0 1 0"/>
       <limit effort="0.0" lower="-3.14159" upper="3.14159" velocity="0.0"/>
    </joint>
    <link name="Head">
        <inertial>
            <origin xyz="-0.09994355625899905 0 0.35759352466788463" rpy="0 0 0"/>
            <mass value="1" />
            <inertia ixx="100" ixy="0" ixz="0" iyy="100" iyz="0" izz="100" />
        </inertial>
        <visual>
            <origin xyz="-0.09994355625899905 0 0.35759352466788463" rpy="0 0 0"/>
            <geometry>
                <box size="0.3997742250359962 0.3473988762434074 0.35759352466788463" />
            </geometry>
            <material name="Cyan">
                <color rgba="0.0 1.0 1.0 1.0"/>
            </material>
        </visual>
        <collision>
            <origin xyz="-0.09994355625899905 0 0.35759352466788463" rpy="0 0 0"/>
            <geometry>
                <box size="0.3997742250359962 0.3473988762434074 0.35759352466788463" />
            </geometry>
        </collision>
    </link>
    <joint name="0_1" type="revolute">
       <parent link="0"/>
       <child  link="1"/>
       <origin rpy="0 0 0" xyz="0.533032300047995 0.3473988762434074 0.23839568311192308" />
     <axis xyz="1 0 0"/>
       <limit effort="0.0" lower="-3.14159" upper="3.14159" velocity="0.0"/>
    </joint>
    <link name="1">
        <inertial>
            <origin xyz="0.08089179600099737 0.31274634134948237 -0.02879522209590853" rpy="0 0 0"/>
            <mass value="1" />
            <inertia ixx="100" ixy="0" ixz="0" iyy="100" iyz="0" izz="100" />
        </inertial>
        <visual>
            <origin xyz="0.08089179600099737 0.31274634134948237 -0.02879522209590853" rpy="0 0 0"/>
            <geometry>
                <box size="0.16178359200199474 0.6254926826989647 0.05759044419181706" />
            </geometry>
            <material name="Green">
                <color rgba="0 1.0 0.0 1.0"/>
            </material>
        </visual>
        <collision>
            <origin xyz="0.08089179600099737 0.31274634134948237 -0.02879522209590853" rpy="0 0 0"/>
            <geometry>
                <box size="0.16178359200199474 0.6254926826989647 0.05759044419181706" />
            </geometry>
        </collision>
    </link>
    <joint name="1_11" type="revolute">
       <parent link="1"/>
       <child  link="11"/>
       <origin rpy="0 0 0" xyz="0.16178359200199474 0.6254926826989647 -0.02879522209590853" />
     <axis xyz="0 1 0"/>
       <limit effort="0.0" lower="-3.14159" upper="3.14159" velocity="0.0"/>
    </joint>
    <link name="11">
        <inertial>
            <origin xyz="0.16329679002237085 -0.07369208439985638 -0.05906262327665057" rpy="0 0 0"/>
            <mass value="1" />
            <inertia ixx="100" ixy="0" ixz="0" iyy="100" iyz="0" izz="100" />
        </inertial>
        <visual>
            <origin xyz="0.16329679002237085 -0.07369208439985638 -0.05906262327665057" rpy="0 0 0"/>
            <geometry>
                <box size="0.3265935800447417 0.14738416879971275 0.11812524655330114" />
            </geometry>
            <material name="Green">
                <color rgba="0 1.0 0.0 1.0"/>
            </material>
        </visual>
        <collision>
            <origin xyz="0.16329679002237085 -0.07369208439985638 -0.05906262327665057" rpy="0 0 0"/>
            <geometry>
                <box size="0.3265935800447417 0.14738416879971275 0.11812524655330114" />
            </geometry>
        </collision>
    </link>
    <joint name="0_2" type="revolute">
       <parent link="0"/>
       <child  link="2"/>
       <origin rpy="0 0 0" xyz="-0.533032300047995 0.3473988762434074 0.23839568311192308" />
     <axis xyz="1 0 0"/>
       <limit effort="0.0" lower="-3.14159" upper="3.14159" velocity="0.0"/>
    </joint>
    <link name="2">
        <inertial>
            <origin xyz="-0.05055785397492936 0.3748215356225927 -0.06696264386298488" rpy="0 0 0"/>
            <mass value="1" />
            <inertia ixx="100" ixy="0" ixz="0" iyy="100" iyz="0" izz="100" />
        </inertial>
        <visual>
            <origin xyz="-0.05055785397492936 0.3748215356225927 -0.06696264386298488" rpy="0 0 0"/>
            <geometry>
                <box size="0.10111570794985872 0.7496430712451854 0.13392528772596976" />
            </geometry>
            <material name="Blue">
                <color rgba="0 0.0 1.0 1.0"/>
            </material>
        </visual>
        <collision>
            <origin xyz="-0.05055785397492936 0.3748215356225927 -0.06696264386298488" rpy="0 0 0"/>
            <geometry>
                <box size="0.10111570794985872 0.7496430712451854 0.13392528772596976" />
            </geometry>
        </collision>
    </link>
    <joint name="2_12" type="revolute">
       <parent link="2"/>
       <child  link="12"/>
       <origin rpy="0 0 0" xyz="-0.10111570794985872 0.7496430712451854 -0.06696264386298488" />
     <axis xyz="0 1 0"/>
       <limit effort="0.0" lower="-3.14159" upper="3.14159" velocity="0.0"/>
    </joint>
    <link name="12">
        <inertial>
            <origin xyz="-0.19803573086205334 -0.13098989288361768 -0.03588383831205478" rpy="0 0 0"/>
            <mass value="1" />
            <inertia ixx="100" ixy="0" ixz="0" iyy="100" iyz="0" izz="100" />
        </inertial>
        <visual>
            <origin xyz="-0.19803573086205334 -0.13098989288361768 -0.03588383831205478" rpy="0 0 0"/>
            <geometry>
                <box size="0.3960714617241067 0.26197978576723535 0.07176767662410956" />
            </geometry>
            <material name="Green">
                <color rgba="0 1.0 0.0 1.0"/>
            </material>
        </visual>
        <collision>
            <origin xyz="-0.19803573086205334 -0.13098989288361768 -0.03588383831205478" rpy="0 0 0"/>
            <geometry>
                <box size="0.3960714617241067 0.26197978576723535 0.07176767662410956" />
            </geometry>
        </collision>
    </link>
    <joint name="0_3" type="revolute">
       <parent link="0"/>
       <child  link="3"/>
       <origin rpy="0 0 0" xyz="-0.533032300047995 -0.3473988762434074 0.23839568311192308" />
     <axis xyz="1 0 0"/>
       <limit effort="0.0" lower="-3.14159" upper="3.14159" velocity="0.0"/>
    </joint>
    <link name="3">
        <inertial>
            <origin xyz="-0.16006855346252158 -0.3252118395303748 -0.0647836080488415" rpy="0 0 0"/>
            <mass value="1" />
            <inertia ixx="100" ixy="0" ixz="0" iyy="100" iyz="0" izz="100" />
        </inertial>
        <visual>
            <origin xyz="-0.16006855346252158 -0.3252118395303748 -0.0647836080488415" rpy="0 0 0"/>
            <geometry>
                <box size="0.32013710692504316 0.6504236790607496 0.129567216097683" />
            </geometry>
            <material name="Blue">
                <color rgba="0 0.0 1.0 1.0"/>
            </material>
        </visual>
        <collision>
            <origin xyz="-0.16006855346252158 -0.3252118395303748 -0.0647836080488415" rpy="0 0 0"/>
            <geometry>
                <box size="0.32013710692504316 0.6504236790607496 0.129567216097683" />
            </geometry>
        </collision>
    </link>
    <joint name="3_13" type="revolute">
       <parent link="3"/>
       <child  link="13"/>
       <origin rpy="0 0 0" xyz="-0.32013710692504316 -0.6504236790607496 -0.0647836080488415" />
     <axis xyz="0 1 0"/>
       <limit effort="0.0" lower="-3.14159" upper="3.14159" velocity="0.0"/>
    </joint>
    <link name="13">
        <inertial>
            <origin xyz="-0.4031563798800909 0.1483699126071799 -0.028341803588743247" rpy="0 0 0"/>
            <mass value="1" />
            <inertia ixx="100" ixy="0" ixz="0" iyy="100" iyz="0" izz="100" />
        </inertial>
        <visual>
            <origin xyz="-0.4031563798800909 0.1483699126071799 -0.028341803588743247" rpy="0 0 0"/>
            <geometry>
                <box size="0.8063127597601818 0.2967398252143598 0.056683607177486495" />
            </geometry>
            <material name="Green">
                <color rgba="0 1.0 0.0 1.0"/>
            </material>
        </visual>
        <collision>
            <origin xyz="-0.4031563798800909 0.1483699126071799 -0.028341803588743247" rpy="0 0 0"/>
            <geometry>
                <box size="0.8063127597601818 0.2967398252143598 0.056683607177486495" />
            </geometry>
        </collision>
    </link>
    <joint name="0_4" type="revolute">
       <parent link="0"/>
       <child  link="4"/>
       <origin rpy="0 0 0" xyz="0.533032300047995 -0.3473988762434074 0.23839568311192308" />
     <axis xyz="1 0 0"/>
       <limit effort="0.0" lower="-3.14159" upper="3.14159" velocity="0.0"/>
    </joint>
    <link name="4">
        <inertial>
            <origin xyz="0.11707517969140702 -0.23820322162216448 -0.078025236051326" rpy="0 0 0"/>
            <mass value="1" />
            <inertia ixx="100" ixy="0" ixz="0" iyy="100" iyz="0" izz="100" />
        </inertial>
        <visual>
            <origin xyz="0.11707517969140702 -0.23820322162216448 -0.078025236051326" rpy="0 0 0"/>
            <geometry>
                <box size="0.23415035938281403 0.47640644324432896 0.156050472102652" />
            </geometry>
            <material name="Blue">
                <color rgba="0 0.0 1.0 1.0"/>
            </material>
        </visual>
        <collision>
            <origin xyz="0.11707517969140702 -0.23820322162216448 -0.078025236051326" rpy="0 0 0"/>
            <geometry>
                <box size="0.23415035938281403 0.47640644324432896 0.156050472102652" />
            </geometry>
        </collision>
    </link>
    <joint name="4_14" type="revolute">
       <parent link="4"/>
       <child  link="14"/>
       <origin rpy="0 0 0" xyz="0.23415035938281403 -0.47640644324432896 -0.078025236051326" />
     <axis xyz="0 1 0"/>
       <limit effort="0.0" lower="-3.14159" upper="3.14159" velocity="0.0"/>
    </joint>
    <link name="14">
        <inertial>
            <origin xyz="0.3160631326661413 0.08640290060617961 -0.027596149025695207" rpy="0 0 0"/>
            <mass value="1" />
            <inertia ixx="100" ixy="0" ixz="0" iyy="100" iyz="0" izz="100" />
        </inertial>
        <visual>
            <origin xyz="0.3160631326661413 0.08640290060617961 -0.027596149025695207" rpy="0 0 0"/>
            <geometry>
                <box size="0.6321262653322826 0.17280580121235922 0.055192298051390414" />
            </geometry>
            <material name="Green">
                <color rgba="0 1.0 0.0 1.0"/>
            </material>
        </visual>
        <collision>
            <origin xyz="0.3160631326661413 0.08640290060617961 -0.027596149025695207" rpy="0 0 0"/>
            <geometry>
                <box size="0.6321262653322826 0.17280580121235922 0.055192298051390414" />
            </geometry>
        </collision>
    </link>
</robot>