<robot name = "robot">
    <link name="0">
        <inertial>
            <origin xyz="0 0 0.15138134364415773" rpy="0 0 0"/>
            <mass value="1" />
            <inertia ixx="100" ixy="0" ixz="0" iyy="100" iyz="0" izz="100" />
        </inertial>
        <visual>
            <origin xyz="0 0 0.15138134364415773" rpy="0 0 0"/>
            <geometry>
                <box size="1.5035625031299265 0.6417115535185957 0.30276268728831546" />
            </geometry>
            <material name="Blue">
                <color rgba="0 0.0 1.0 1.0"/>
            </material>
        </visual>
        <collision>
            <origin xyz="0 0 0.15138134364415773" rpy="0 0 0"/>
            <geometry>
                <box size="1.5035625031299265 0.6417115535185957 0.30276268728831546" />
            </geometry>
        </collision>
    </link>
    <joint name="0_Head" type="revolute">
       <parent link="0"/>
       <child  link="Head"/>
       <origin rpy="0 0 0" xyz="-0.7517812515649632 0 0.15138134364415773" />
     <axis xyz="0 1 0"/>
       <limit effort="0.0" lower="-3.14159" upper="3.14159" velocity="0.0"/>
    </joint>
    <link name="Head">
        <inertial>
            <origin xyz="-0.0939726564456204 0 0.2270720154662366" rpy="0 0 0"/>
            <mass value="1" />
            <inertia ixx="100" ixy="0" ixz="0" iyy="100" iyz="0" izz="100" />
        </inertial>
        <visual>
            <origin xyz="-0.0939726564456204 0 0.2270720154662366" rpy="0 0 0"/>
            <geometry>
                <box size="0.3758906257824816 0.32085577675929783 0.2270720154662366" />
            </geometry>
            <material name="Cyan">
                <color rgba="0.0 1.0 1.0 1.0"/>
            </material>
        </visual>
        <collision>
            <origin xyz="-0.0939726564456204 0 0.2270720154662366" rpy="0 0 0"/>
            <geometry>
                <box size="0.3758906257824816 0.32085577675929783 0.2270720154662366" />
            </geometry>
        </collision>
    </link>
    <joint name="0_1" type="revolute">
       <parent link="0"/>
       <child  link="1"/>
       <origin rpy="0 0 0" xyz="0.5011875010433088 0.32085577675929783 0.15138134364415773" />
     <axis xyz="1 0 0"/>
       <limit effort="0.0" lower="-3.14159" upper="3.14159" velocity="0.0"/>
    </joint>
    <link name="1">
        <inertial>
            <origin xyz="0.15766030157677505 0.39441763450445894 -0.036076363988555245" rpy="0 0 0"/>
            <mass value="1" />
            <inertia ixx="100" ixy="0" ixz="0" iyy="100" iyz="0" izz="100" />
        </inertial>
        <visual>
            <origin xyz="0.15766030157677505 0.39441763450445894 -0.036076363988555245" rpy="0 0 0"/>
            <geometry>
                <box size="0.3153206031535501 0.7888352690089179 0.07215272797711049" />
            </geometry>
            <material name="Green">
                <color rgba="0 1.0 0.0 1.0"/>
            </material>
        </visual>
        <collision>
            <origin xyz="0.15766030157677505 0.39441763450445894 -0.036076363988555245" rpy="0 0 0"/>
            <geometry>
                <box size="0.3153206031535501 0.7888352690089179 0.07215272797711049" />
            </geometry>
        </collision>
    </link>
    <joint name="1_11" type="revolute">
       <parent link="1"/>
       <child  link="11"/>
       <origin rpy="0 0 0" xyz="0.3153206031535501 0.7888352690089179 -0.036076363988555245" />
     <axis xyz="0 1 0"/>
       <limit effort="0.0" lower="-3.14159" upper="3.14159" velocity="0.0"/>
    </joint>
    <link name="11">
        <inertial>
            <origin xyz="0.1552303758442594 -0.09962046146420682 -0.061655316783360635" rpy="0 0 0"/>
            <mass value="1" />
            <inertia ixx="100" ixy="0" ixz="0" iyy="100" iyz="0" izz="100" />
        </inertial>
        <visual>
            <origin xyz="0.1552303758442594 -0.09962046146420682 -0.061655316783360635" rpy="0 0 0"/>
            <geometry>
                <box size="0.3104607516885188 0.19924092292841364 0.12331063356672127" />
            </geometry>
            <material name="Green">
                <color rgba="0 1.0 0.0 1.0"/>
            </material>
        </visual>
        <collision>
            <origin xyz="0.1552303758442594 -0.09962046146420682 -0.061655316783360635" rpy="0 0 0"/>
            <geometry>
                <box size="0.3104607516885188 0.19924092292841364 0.12331063356672127" />
            </geometry>
        </collision>
    </link>
    <joint name="0_2" type="revolute">
       <parent link="0"/>
       <child  link="2"/>
       <origin rpy="0 0 0" xyz="-0.5011875010433088 0.32085577675929783 0.15138134364415773" />
     <axis xyz="1 0 0"/>
       <limit effort="0.0" lower="-3.14159" upper="3.14159" velocity="0.0"/>
    </joint>
    <link name="2">
        <inertial>
            <origin xyz="-0.15807494734134392 0.36663384957767686 -0.05368765828206776" rpy="0 0 0"/>
            <mass value="1" />
            <inertia ixx="100" ixy="0" ixz="0" iyy="100" iyz="0" izz="100" />
        </inertial>
        <visual>
            <origin xyz="-0.15807494734134392 0.36663384957767686 -0.05368765828206776" rpy="0 0 0"/>
            <geometry>
                <box size="0.31614989468268784 0.7332676991553537 0.10737531656413551" />
            </geometry>
            <material name="Green">
                <color rgba="0 1.0 0.0 1.0"/>
            </material>
        </visual>
        <collision>
            <origin xyz="-0.15807494734134392 0.36663384957767686 -0.05368765828206776" rpy="0 0 0"/>
            <geometry>
                <box size="0.31614989468268784 0.7332676991553537 0.10737531656413551" />
            </geometry>
        </collision>
    </link>
    <joint name="2_12" type="revolute">
       <parent link="2"/>
       <child  link="12"/>
       <origin rpy="0 0 0" xyz="-0.31614989468268784 0.7332676991553537 -0.05368765828206776" />
     <axis xyz="0 1 0"/>
       <limit effort="0.0" lower="-3.14159" upper="3.14159" velocity="0.0"/>
    </joint>
    <link name="12">
        <inertial>
            <origin xyz="-0.16972779198404642 -0.18112490641826767 -0.034068575631362626" rpy="0 0 0"/>
            <mass value="1" />
            <inertia ixx="100" ixy="0" ixz="0" iyy="100" iyz="0" izz="100" />
        </inertial>
        <visual>
            <origin xyz="-0.16972779198404642 -0.18112490641826767 -0.034068575631362626" rpy="0 0 0"/>
            <geometry>
                <box size="0.33945558396809283 0.36224981283653535 0.06813715126272525" />
            </geometry>
            <material name="Green">
                <color rgba="0 1.0 0.0 1.0"/>
            </material>
        </visual>
        <collision>
            <origin xyz="-0.16972779198404642 -0.18112490641826767 -0.034068575631362626" rpy="0 0 0"/>
            <geometry>
                <box size="0.33945558396809283 0.36224981283653535 0.06813715126272525" />
            </geometry>
        </collision>
    </link>
    <joint name="0_3" type="revolute">
       <parent link="0"/>
       <child  link="3"/>
       <origin rpy="0 0 0" xyz="-0.5011875010433088 -0.32085577675929783 0.15138134364415773" />
     <axis xyz="1 0 0"/>
       <limit effort="0.0" lower="-3.14159" upper="3.14159" velocity="0.0"/>
    </joint>
    <link name="3">
        <inertial>
            <origin xyz="-0.209362173538658 -0.35728072411510436 -0.08872641240618359" rpy="0 0 0"/>
            <mass value="1" />
            <inertia ixx="100" ixy="0" ixz="0" iyy="100" iyz="0" izz="100" />
        </inertial>
        <visual>
            <origin xyz="-0.209362173538658 -0.35728072411510436 -0.08872641240618359" rpy="0 0 0"/>
            <geometry>
                <box size="0.418724347077316 0.7145614482302087 0.17745282481236718" />
            </geometry>
            <material name="Blue">
                <color rgba="0 0.0 1.0 1.0"/>
            </material>
        </visual>
        <collision>
            <origin xyz="-0.209362173538658 -0.35728072411510436 -0.08872641240618359" rpy="0 0 0"/>
            <geometry>
                <box size="0.418724347077316 0.7145614482302087 0.17745282481236718" />
            </geometry>
        </collision>
    </link>
    <joint name="3_13" type="revolute">
       <parent link="3"/>
       <child  link="13"/>
       <origin rpy="0 0 0" xyz="-0.418724347077316 -0.7145614482302087 -0.08872641240618359" />
     <axis xyz="0 1 0"/>
       <limit effort="0.0" lower="-3.14159" upper="3.14159" velocity="0.0"/>
    </joint>
    <link name="13">
        <inertial>
            <origin xyz="-0.39090842090803013 0.19766713108169504 -0.03156001977752913" rpy="0 0 0"/>
            <mass value="1" />
            <inertia ixx="100" ixy="0" ixz="0" iyy="100" iyz="0" izz="100" />
        </inertial>
        <visual>
            <origin xyz="-0.39090842090803013 0.19766713108169504 -0.03156001977752913" rpy="0 0 0"/>
            <geometry>
                <box size="0.7818168418160603 0.39533426216339007 0.06312003955505827" />
            </geometry>
            <material name="Blue">
                <color rgba="0 0.0 1.0 1.0"/>
            </material>
        </visual>
        <collision>
            <origin xyz="-0.39090842090803013 0.19766713108169504 -0.03156001977752913" rpy="0 0 0"/>
            <geometry>
                <box size="0.7818168418160603 0.39533426216339007 0.06312003955505827" />
            </geometry>
        </collision>
    </link>
    <joint name="0_4" type="revolute">
       <parent link="0"/>
       <child  link="4"/>
       <origin rpy="0 0 0" xyz="0.5011875010433088 -0.32085577675929783 0.15138134364415773" />
     <axis xyz="1 0 0"/>
       <limit effort="0.0" lower="-3.14159" upper="3.14159" velocity="0.0"/>
    </joint>
    <link name="4">
        <inertial>
            <origin xyz="0.23608679221857332 -0.20340496631559035 -0.08078844397112811" rpy="0 0 0"/>
            <mass value="1" />
            <inertia ixx="100" ixy="0" ixz="0" iyy="100" iyz="0" izz="100" />
        </inertial>
        <visual>
            <origin xyz="0.23608679221857332 -0.20340496631559035 -0.08078844397112811" rpy="0 0 0"/>
            <geometry>
                <box size="0.47217358443714663 0.4068099326311807 0.16157688794225622" />
            </geometry>
            <material name="Blue">
                <color rgba="0 0.0 1.0 1.0"/>
            </material>
        </visual>
        <collision>
            <origin xyz="0.23608679221857332 -0.20340496631559035 -0.08078844397112811" rpy="0 0 0"/>
            <geometry>
                <box size="0.47217358443714663 0.4068099326311807 0.16157688794225622" />
            </geometry>
        </collision>
    </link>
    <joint name="4_14" type="revolute">
       <parent link="4"/>
       <child  link="14"/>
       <origin rpy="0 0 0" xyz="0.47217358443714663 -0.4068099326311807 -0.08078844397112811" />
     <axis xyz="0 1 0"/>
       <limit effort="0.0" lower="-3.14159" upper="3.14159" velocity="0.0"/>
    </joint>
    <link name="14">
        <inertial>
            <origin xyz="0.20934622242822326 0.1411755434515787 -0.09500234699924145" rpy="0 0 0"/>
            <mass value="1" />
            <inertia ixx="100" ixy="0" ixz="0" iyy="100" iyz="0" izz="100" />
        </inertial>
        <visual>
            <origin xyz="0.20934622242822326 0.1411755434515787 -0.09500234699924145" rpy="0 0 0"/>
            <geometry>
                <box size="0.4186924448564465 0.2823510869031574 0.1900046939984829" />
            </geometry>
            <material name="Green">
                <color rgba="0 1.0 0.0 1.0"/>
            </material>
        </visual>
        <collision>
            <origin xyz="0.20934622242822326 0.1411755434515787 -0.09500234699924145" rpy="0 0 0"/>
            <geometry>
                <box size="0.4186924448564465 0.2823510869031574 0.1900046939984829" />
            </geometry>
        </collision>
    </link>
</robot>