<robot name = "robot">
    <link name="0">
        <inertial>
            <origin xyz="0 0 0.9632373648236108" rpy="0 0 0"/>
            <mass value="1" />
            <inertia ixx="100" ixy="0" ixz="0" iyy="100" iyz="0" izz="100" />
        </inertial>
        <visual>
            <origin xyz="0 0 0.9632373648236108" rpy="0 0 0"/>
            <geometry>
                <box size="1.535756402746712 0.5496474095927861 0.3264747296472214" />
            </geometry>
            <material name="Blue">
                <color rgba="0.0 0.0 1.0 1.0"/>
            </material>
        </visual>
        <collision>
            <origin xyz="0 0 0.9632373648236108" rpy="0 0 0"/>
            <geometry>
                <box size="1.535756402746712 0.5496474095927861 0.3264747296472214" />
            </geometry>
        </collision>
    </link>
    <joint name="0_Head" type="revolute">
       <parent link="0"/>
       <child  link="Head"/>
       <origin rpy="0 0 0" xyz="-0.767878201373356 0 0.9632373648236108" />
     <axis xyz="0 1 0"/>
       <limit effort="0.0" lower="-3.14159" upper="3.14159" velocity="0.0"/>
    </joint>
    <link name="Head">
        <inertial>
            <origin xyz="-0.0959847751716695 0 0.3264747296472214" rpy="0 0 0"/>
            <mass value="1" />
            <inertia ixx="100" ixy="0" ixz="0" iyy="100" iyz="0" izz="100" />
        </inertial>
        <visual>
            <origin xyz="-0.0959847751716695 0 0.3264747296472214" rpy="0 0 0"/>
            <geometry>
                <box size="0.383939100686678 0.27482370479639306 0.3264747296472214" />
            </geometry>
            <material name="Blue">
                <color rgba="0.0 0.0 1.0 1.0"/>
            </material>
        </visual>
        <collision>
            <origin xyz="-0.0959847751716695 0 0.3264747296472214" rpy="0 0 0"/>
            <geometry>
                <box size="0.383939100686678 0.27482370479639306 0.3264747296472214" />
            </geometry>
        </collision>
    </link>
    <joint name="0_2" type="revolute">
       <parent link="0"/>
       <child  link="2"/>
       <origin rpy="0 0 0" xyz="-0.5119188009155707 0.27482370479639306 0.9632373648236108" />
     <axis xyz="0 1 0"/>
       <limit effort="0.0" lower="-3.14159" upper="3.14159" velocity="0.0"/>
    </joint>
    <link name="2">
        <inertial>
            <origin xyz="0 0.06828199443767997 -0.45" rpy="0 0 0"/>
            <mass value="1" />
            <inertia ixx="100" ixy="0" ixz="0" iyy="100" iyz="0" izz="100" />
        </inertial>
        <visual>
            <origin xyz="0 0.06828199443767997 -0.45" rpy="0 0 0"/>
            <geometry>
                <box size="0.2083237223469011 0.13656398887535995 0.9" />
            </geometry>
            <material name="G">
                <color rgba="0 1.0 0.0 1.0"/>
            </material>
        </visual>
        <collision>
            <origin xyz="0 0.06828199443767997 -0.45" rpy="0 0 0"/>
            <geometry>
                <box size="0.2083237223469011 0.13656398887535995 0.9" />
            </geometry>
        </collision>
    </link>
    <joint name="2_12" type="revolute">
       <parent link="2"/>
       <child  link="12"/>
       <origin rpy="0 0 0" xyz="-0.10416186117345055 0.06828199443767997 -0.9" />
     <axis xyz="0 1 0"/>
       <limit effort="0.0" lower="-3.14159" upper="3.14159" velocity="0.0"/>
    </joint>
    <link name="12">
        <inertial>
            <origin xyz="-0.26360674292392916 0 0" rpy="0 0 0"/>
            <mass value="1" />
            <inertia ixx="100" ixy="0" ixz="0" iyy="100" iyz="0" izz="100" />
        </inertial>
        <visual>
            <origin xyz="-0.26360674292392916 0 0" rpy="0 0 0"/>
            <geometry>
                <box size="0.5272134858478583 0.13656398887535995 0.1" />
            </geometry>
            <material name="B">
                <color rgba="0 1.0 0.0 1.0"/>
            </material>
        </visual>
        <collision>
            <origin xyz="-0.26360674292392916 0 0" rpy="0 0 0"/>
            <geometry>
                <box size="0.5272134858478583 0.13656398887535995 0.1" />
            </geometry>
        </collision>
    </link>
</robot>