<robot name = "robot">
    <link name="0">
        <inertial>
            <origin xyz="0 0 0.9087367598963632" rpy="0 0 0"/>
            <mass value="1" />
            <inertia ixx="100" ixy="0" ixz="0" iyy="100" iyz="0" izz="100" />
        </inertial>
        <visual>
            <origin xyz="0 0 0.9087367598963632" rpy="0 0 0"/>
            <geometry>
                <box size="1.5824576247257165 1.4898557682248115 0.2174735197927263" />
            </geometry>
            <material name="Blue">
                <color rgba="0.0 0.0 1.0 1.0"/>
            </material>
        </visual>
        <collision>
            <origin xyz="0 0 0.9087367598963632" rpy="0 0 0"/>
            <geometry>
                <box size="1.5824576247257165 1.4898557682248115 0.2174735197927263" />
            </geometry>
        </collision>
    </link>
    <joint name="0_Head" type="revolute">
       <parent link="0"/>
       <child  link="Head"/>
       <origin rpy="0 0 0" xyz="-0.7912288123628582 0 0.9087367598963632" />
     <axis xyz="0 1 0"/>
       <limit effort="0.0" lower="-3.14159" upper="3.14159" velocity="0.0"/>
    </joint>
    <link name="Head">
        <inertial>
            <origin xyz="-0.09890360154535728 0 0.2174735197927263" rpy="0 0 0"/>
            <mass value="1" />
            <inertia ixx="100" ixy="0" ixz="0" iyy="100" iyz="0" izz="100" />
        </inertial>
        <visual>
            <origin xyz="-0.09890360154535728 0 0.2174735197927263" rpy="0 0 0"/>
            <geometry>
                <box size="0.3956144061814291 0.7449278841124057 0.2174735197927263" />
            </geometry>
            <material name="Blue">
                <color rgba="0.0 0.0 1.0 1.0"/>
            </material>
        </visual>
        <collision>
            <origin xyz="-0.09890360154535728 0 0.2174735197927263" rpy="0 0 0"/>
            <geometry>
                <box size="0.3956144061814291 0.7449278841124057 0.2174735197927263" />
            </geometry>
        </collision>
    </link>
</robot>