<robot name = "robot">
    <link name="0">
        <inertial>
            <origin xyz="0 0 0.17093878563781106" rpy="0 0 0"/>
            <mass value="1" />
            <inertia ixx="100" ixy="0" ixz="0" iyy="100" iyz="0" izz="100" />
        </inertial>
        <visual>
            <origin xyz="0 0 0.17093878563781106" rpy="0 0 0"/>
            <geometry>
                <box size="1.7368813887897647 0.9370360125644497 0.3418775712756221" />
            </geometry>
            <material name="Green">
                <color rgba="0 1.0 0.0 1.0"/>
            </material>
        </visual>
        <collision>
            <origin xyz="0 0 0.17093878563781106" rpy="0 0 0"/>
            <geometry>
                <box size="1.7368813887897647 0.9370360125644497 0.3418775712756221" />
            </geometry>
        </collision>
    </link>
    <joint name="0_Head" type="revolute">
       <parent link="0"/>
       <child  link="Head"/>
       <origin rpy="0 0 0" xyz="-0.8684406943948824 0 0.17093878563781106" />
     <axis xyz="0 1 0"/>
       <limit effort="0.0" lower="-3.14159" upper="3.14159" velocity="0.0"/>
    </joint>
    <link name="Head">
        <inertial>
            <origin xyz="-0.1085550867993603 0 0.2564081784567166" rpy="0 0 0"/>
            <mass value="1" />
            <inertia ixx="100" ixy="0" ixz="0" iyy="100" iyz="0" izz="100" />
        </inertial>
        <visual>
            <origin xyz="-0.1085550867993603 0 0.2564081784567166" rpy="0 0 0"/>
            <geometry>
                <box size="0.4342203471974412 0.46851800628222484 0.2564081784567166" />
            </geometry>
            <material name="Blue">
                <color rgba="0.0 0.0 1.0 1.0"/>
            </material>
        </visual>
        <collision>
            <origin xyz="-0.1085550867993603 0 0.2564081784567166" rpy="0 0 0"/>
            <geometry>
                <box size="0.4342203471974412 0.46851800628222484 0.2564081784567166" />
            </geometry>
        </collision>
    </link>
    <joint name="0_3" type="revolute">
       <parent link="0"/>
       <child  link="3"/>
       <origin rpy="0 0 0" xyz="-0.5789604629299215 -0.46851800628222484 0.17093878563781106" />
     <axis xyz="0 1 0"/>
       <limit effort="0.0" lower="-3.14159" upper="3.14159" velocity="0.0"/>
    </joint>
    <link name="3">
        <inertial>
            <origin xyz="-0.217354767428093 -0.20009795753886678 -0.4964033747305495" rpy="0 0 0"/>
            <mass value="1" />
            <inertia ixx="100" ixy="0" ixz="0" iyy="100" iyz="0" izz="100" />
        </inertial>
        <visual>
            <origin xyz="-0.217354767428093 -0.20009795753886678 -0.4964033747305495" rpy="0 0 0"/>
            <geometry>
                <box size="0.434709534856186 0.40019591507773355 0.992806749461099" />
            </geometry>
            <material name="Green">
                <color rgba="0 1.0 0.0 1.0"/>
            </material>
        </visual>
        <collision>
            <origin xyz="-0.217354767428093 -0.20009795753886678 -0.4964033747305495" rpy="0 0 0"/>
            <geometry>
                <box size="0.434709534856186 0.40019591507773355 0.992806749461099" />
            </geometry>
        </collision>
    </link>
    <joint name="3_13" type="revolute">
       <parent link="3"/>
       <child  link="13"/>
       <origin rpy="0 0 0" xyz="-0.434709534856186 -0.40019591507773355 -0.4964033747305495" />
     <axis xyz="0 1 0"/>
       <limit effort="0.0" lower="-3.14159" upper="3.14159" velocity="0.0"/>
    </joint>
    <link name="13">
        <inertial>
            <origin xyz="-0.2010510434935499 0.14858296398883883 -0.03456705782576426" rpy="0 0 0"/>
            <mass value="1" />
            <inertia ixx="100" ixy="0" ixz="0" iyy="100" iyz="0" izz="100" />
        </inertial>
        <visual>
            <origin xyz="-0.2010510434935499 0.14858296398883883 -0.03456705782576426" rpy="0 0 0"/>
            <geometry>
                <box size="0.4021020869870998 0.29716592797767766 0.06913411565152852" />
            </geometry>
            <material name="Green">
                <color rgba="0 1.0 0.0 1.0"/>
            </material>
        </visual>
        <collision>
            <origin xyz="-0.2010510434935499 0.14858296398883883 -0.03456705782576426" rpy="0 0 0"/>
            <geometry>
                <box size="0.4021020869870998 0.29716592797767766 0.06913411565152852" />
            </geometry>
        </collision>
    </link>
    <joint name="0_4" type="revolute">
       <parent link="0"/>
       <child  link="4"/>
       <origin rpy="0 0 0" xyz="0.5789604629299215 -0.46851800628222484 0.17093878563781106" />
     <axis xyz="0 1 0"/>
       <limit effort="0.0" lower="-3.14159" upper="3.14159" velocity="0.0"/>
    </joint>
    <link name="4">
        <inertial>
            <origin xyz="0.20750103793578423 -0.21997349077040668 -0.6900057161328719" rpy="0 0 0"/>
            <mass value="1" />
            <inertia ixx="100" ixy="0" ixz="0" iyy="100" iyz="0" izz="100" />
        </inertial>
        <visual>
            <origin xyz="0.20750103793578423 -0.21997349077040668 -0.6900057161328719" rpy="0 0 0"/>
            <geometry>
                <box size="0.41500207587156845 0.43994698154081335 1.3800114322657437" />
            </geometry>
            <material name="Green">
                <color rgba="0 1.0 0.0 1.0"/>
            </material>
        </visual>
        <collision>
            <origin xyz="0.20750103793578423 -0.21997349077040668 -0.6900057161328719" rpy="0 0 0"/>
            <geometry>
                <box size="0.41500207587156845 0.43994698154081335 1.3800114322657437" />
            </geometry>
        </collision>
    </link>
</robot>