<robot name = "robot">
    <link name="0">
        <inertial>
            <origin xyz="0 0 0.21460389334188557" rpy="0 0 0"/>
            <mass value="1" />
            <inertia ixx="100" ixy="0" ixz="0" iyy="100" iyz="0" izz="100" />
        </inertial>
        <visual>
            <origin xyz="0 0 0.21460389334188557" rpy="0 0 0"/>
            <geometry>
                <box size="1.6686860464787945 0.8210927181843265 0.42920778668377113" />
            </geometry>
            <material name="Green">
                <color rgba="0 1.0 0.0 1.0"/>
            </material>
        </visual>
        <collision>
            <origin xyz="0 0 0.21460389334188557" rpy="0 0 0"/>
            <geometry>
                <box size="1.6686860464787945 0.8210927181843265 0.42920778668377113" />
            </geometry>
        </collision>
    </link>
    <joint name="0_Head" type="revolute">
       <parent link="0"/>
       <child  link="Head"/>
       <origin rpy="0 0 0" xyz="-0.8343430232393972 0 0.21460389334188557" />
     <axis xyz="0 1 0"/>
       <limit effort="0.0" lower="-3.14159" upper="3.14159" velocity="0.0"/>
    </joint>
    <link name="Head">
        <inertial>
            <origin xyz="-0.25 0 0.25" rpy="0 0 0"/>
            <mass value="1" />
            <inertia ixx="100" ixy="0" ixz="0" iyy="100" iyz="0" izz="100" />
        </inertial>
        <visual>
            <origin xyz="-0.25 0 0.25" rpy="0 0 0"/>
            <geometry>
                <box size="0.5 0.5 0.5" />
            </geometry>
            <material name="Cyan">
                <color rgba="0.0 1.0 1.0 1.0"/>
            </material>
        </visual>
        <collision>
            <origin xyz="-0.25 0 0.25" rpy="0 0 0"/>
            <geometry>
                <box size="0.5 0.5 0.5" />
            </geometry>
        </collision>
    </link>
    <joint name="0_1" type="revolute">
       <parent link="0"/>
       <child  link="1"/>
       <origin rpy="0 0 0" xyz="0.5562286821595982 0.41054635909216325 0.21460389334188557" />
     <axis xyz="1 0 0"/>
       <limit effort="0.0" lower="-3.14159" upper="3.14159" velocity="0.0"/>
    </joint>
    <link name="1">
        <inertial>
            <origin xyz="0.0772090069676733 0.29745682309909727 -0.049775732378856734" rpy="0 0 0"/>
            <mass value="1" />
            <inertia ixx="100" ixy="0" ixz="0" iyy="100" iyz="0" izz="100" />
        </inertial>
        <visual>
            <origin xyz="0.0772090069676733 0.29745682309909727 -0.049775732378856734" rpy="0 0 0"/>
            <geometry>
                <box size="0.1544180139353466 0.5949136461981945 0.09955146475771347" />
            </geometry>
            <material name="Blue">
                <color rgba="0 0.0 1.0 1.0"/>
            </material>
        </visual>
        <collision>
            <origin xyz="0.0772090069676733 0.29745682309909727 -0.049775732378856734" rpy="0 0 0"/>
            <geometry>
                <box size="0.1544180139353466 0.5949136461981945 0.09955146475771347" />
            </geometry>
        </collision>
    </link>
    <joint name="1_11" type="revolute">
       <parent link="1"/>
       <child  link="11"/>
       <origin rpy="0 0 0" xyz="0.1544180139353466 0.5949136461981945 -0.049775732378856734" />
     <axis xyz="0 1 0"/>
       <limit effort="0.0" lower="-3.14159" upper="3.14159" velocity="0.0"/>
    </joint>
    <link name="11">
        <inertial>
            <origin xyz="0.4570113134752053 -0.1802043027899109 -0.1" rpy="0 0 0"/>
            <mass value="1" />
            <inertia ixx="100" ixy="0" ixz="0" iyy="100" iyz="0" izz="100" />
        </inertial>
        <visual>
            <origin xyz="0.4570113134752053 -0.1802043027899109 -0.1" rpy="0 0 0"/>
            <geometry>
                <box size="0.9140226269504106 0.3604086055798218 0.2" />
            </geometry>
            <material name="Blue">
                <color rgba="0 0.0 1.0 1.0"/>
            </material>
        </visual>
        <collision>
            <origin xyz="0.4570113134752053 -0.1802043027899109 -0.1" rpy="0 0 0"/>
            <geometry>
                <box size="0.9140226269504106 0.3604086055798218 0.2" />
            </geometry>
        </collision>
    </link>
    <joint name="0_2" type="revolute">
       <parent link="0"/>
       <child  link="2"/>
       <origin rpy="0 0 0" xyz="-0.5562286821595982 0.41054635909216325 0.21460389334188557" />
     <axis xyz="1 0 0"/>
       <limit effort="0.0" lower="-3.14159" upper="3.14159" velocity="0.0"/>
    </joint>
    <link name="2">
        <inertial>
            <origin xyz="-0.18297300851876913 0.36805463514072745 -0.08496200797024628" rpy="0 0 0"/>
            <mass value="1" />
            <inertia ixx="100" ixy="0" ixz="0" iyy="100" iyz="0" izz="100" />
        </inertial>
        <visual>
            <origin xyz="-0.18297300851876913 0.36805463514072745 -0.08496200797024628" rpy="0 0 0"/>
            <geometry>
                <box size="0.36594601703753826 0.7361092702814549 0.16992401594049256" />
            </geometry>
            <material name="Blue">
                <color rgba="0 0.0 1.0 1.0"/>
            </material>
        </visual>
        <collision>
            <origin xyz="-0.18297300851876913 0.36805463514072745 -0.08496200797024628" rpy="0 0 0"/>
            <geometry>
                <box size="0.36594601703753826 0.7361092702814549 0.16992401594049256" />
            </geometry>
        </collision>
    </link>
    <joint name="2_12" type="revolute">
       <parent link="2"/>
       <child  link="12"/>
       <origin rpy="0 0 0" xyz="0 0.7361092702814549 -0.08496200797024628" />
     <axis xyz="0 1 0"/>
       <limit effort="0.0" lower="-3.14159" upper="3.14159" velocity="0.0"/>
    </joint>
    <link name="12">
        <inertial>
            <origin xyz="0.1769677387137204 -0.16998382608087698 -0.1" rpy="0 0 0"/>
            <mass value="1" />
            <inertia ixx="100" ixy="0" ixz="0" iyy="100" iyz="0" izz="100" />
        </inertial>
        <visual>
            <origin xyz="0.1769677387137204 -0.16998382608087698 -0.1" rpy="0 0 0"/>
            <geometry>
                <box size="0.3539354774274408 0.33996765216175395 0.2" />
            </geometry>
            <material name="Green">
                <color rgba="0 1.0 0.0 1.0"/>
            </material>
        </visual>
        <collision>
            <origin xyz="0.1769677387137204 -0.16998382608087698 -0.1" rpy="0 0 0"/>
            <geometry>
                <box size="0.3539354774274408 0.33996765216175395 0.2" />
            </geometry>
        </collision>
    </link>
    <joint name="0_3" type="revolute">
       <parent link="0"/>
       <child  link="3"/>
       <origin rpy="0 0 0" xyz="-0.5562286821595982 -0.41054635909216325 0.21460389334188557" />
     <axis xyz="1 0 0"/>
       <limit effort="0.0" lower="-3.14159" upper="3.14159" velocity="0.0"/>
    </joint>
    <link name="3">
        <inertial>
            <origin xyz="-0.18582240588294774 -0.46726292350858095 -0.03481818712827622" rpy="0 0 0"/>
            <mass value="1" />
            <inertia ixx="100" ixy="0" ixz="0" iyy="100" iyz="0" izz="100" />
        </inertial>
        <visual>
            <origin xyz="-0.18582240588294774 -0.46726292350858095 -0.03481818712827622" rpy="0 0 0"/>
            <geometry>
                <box size="0.3716448117658955 0.9345258470171619 0.06963637425655245" />
            </geometry>
            <material name="Blue">
                <color rgba="0 0.0 1.0 1.0"/>
            </material>
        </visual>
        <collision>
            <origin xyz="-0.18582240588294774 -0.46726292350858095 -0.03481818712827622" rpy="0 0 0"/>
            <geometry>
                <box size="0.3716448117658955 0.9345258470171619 0.06963637425655245" />
            </geometry>
        </collision>
    </link>
    <joint name="3_13" type="revolute">
       <parent link="3"/>
       <child  link="13"/>
       <origin rpy="0 0 0" xyz="0 -0.9345258470171619 -0.03481818712827622" />
     <axis xyz="0 1 0"/>
       <limit effort="0.0" lower="-3.14159" upper="3.14159" velocity="0.0"/>
    </joint>
    <link name="13">
        <inertial>
            <origin xyz="0.31450164202416636 0.14012827301036626 -0.1" rpy="0 0 0"/>
            <mass value="1" />
            <inertia ixx="100" ixy="0" ixz="0" iyy="100" iyz="0" izz="100" />
        </inertial>
        <visual>
            <origin xyz="0.31450164202416636 0.14012827301036626 -0.1" rpy="0 0 0"/>
            <geometry>
                <box size="0.6290032840483327 0.2802565460207325 0.2" />
            </geometry>
            <material name="Green">
                <color rgba="0 1.0 0.0 1.0"/>
            </material>
        </visual>
        <collision>
            <origin xyz="0.31450164202416636 0.14012827301036626 -0.1" rpy="0 0 0"/>
            <geometry>
                <box size="0.6290032840483327 0.2802565460207325 0.2" />
            </geometry>
        </collision>
    </link>
    <joint name="0_4" type="revolute">
       <parent link="0"/>
       <child  link="4"/>
       <origin rpy="0 0 0" xyz="0.5562286821595982 -0.41054635909216325 0.21460389334188557" />
     <axis xyz="1 0 0"/>
       <limit effort="0.0" lower="-3.14159" upper="3.14159" velocity="0.0"/>
    </joint>
    <link name="4">
        <inertial>
            <origin xyz="0.17982202511457734 -0.49284540807814303 -0.03495374715337263" rpy="0 0 0"/>
            <mass value="1" />
            <inertia ixx="100" ixy="0" ixz="0" iyy="100" iyz="0" izz="100" />
        </inertial>
        <visual>
            <origin xyz="0.17982202511457734 -0.49284540807814303 -0.03495374715337263" rpy="0 0 0"/>
            <geometry>
                <box size="0.3596440502291547 0.9856908161562861 0.06990749430674525" />
            </geometry>
            <material name="Green">
                <color rgba="0 1.0 0.0 1.0"/>
            </material>
        </visual>
        <collision>
            <origin xyz="0.17982202511457734 -0.49284540807814303 -0.03495374715337263" rpy="0 0 0"/>
            <geometry>
                <box size="0.3596440502291547 0.9856908161562861 0.06990749430674525" />
            </geometry>
        </collision>
    </link>
    <joint name="4_14" type="revolute">
       <parent link="4"/>
       <child  link="14"/>
       <origin rpy="0 0 0" xyz="0.3596440502291547 -0.9856908161562861 -0.03495374715337263" />
     <axis xyz="0 1 0"/>
       <limit effort="0.0" lower="-3.14159" upper="3.14159" velocity="0.0"/>
    </joint>
    <link name="14">
        <inertial>
            <origin xyz="0.17106823458400477 0.19796559353442983 -0.1" rpy="0 0 0"/>
            <mass value="1" />
            <inertia ixx="100" ixy="0" ixz="0" iyy="100" iyz="0" izz="100" />
        </inertial>
        <visual>
            <origin xyz="0.17106823458400477 0.19796559353442983 -0.1" rpy="0 0 0"/>
            <geometry>
                <box size="0.34213646916800955 0.39593118706885966 0.2" />
            </geometry>
            <material name="Blue">
                <color rgba="0 0.0 1.0 1.0"/>
            </material>
        </visual>
        <collision>
            <origin xyz="0.17106823458400477 0.19796559353442983 -0.1" rpy="0 0 0"/>
            <geometry>
                <box size="0.34213646916800955 0.39593118706885966 0.2" />
            </geometry>
        </collision>
    </link>
</robot>