<robot name = "robot">
    <link name="0">
        <inertial>
            <origin xyz="0 0 1.695886016691859" rpy="0 0 0"/>
            <mass value="1" />
            <inertia ixx="100" ixy="0" ixz="0" iyy="100" iyz="0" izz="100" />
        </inertial>
        <visual>
            <origin xyz="0 0 1.695886016691859" rpy="0 0 0"/>
            <geometry>
                <box size="1.6468356283999075 0.8987611450083047 0.3917720333837179" />
            </geometry>
            <material name="Green">
                <color rgba="0 1.0 0.0 1.0"/>
            </material>
        </visual>
        <collision>
            <origin xyz="0 0 1.695886016691859" rpy="0 0 0"/>
            <geometry>
                <box size="1.6468356283999075 0.8987611450083047 0.3917720333837179" />
            </geometry>
        </collision>
    </link>
    <joint name="0_Head" type="revolute">
       <parent link="0"/>
       <child  link="Head"/>
       <origin rpy="0 0 0" xyz="-0.8234178141999537 0 1.695886016691859" />
     <axis xyz="0 1 0"/>
       <limit effort="0.0" lower="-3.14159" upper="3.14159" velocity="0.0"/>
    </joint>
    <link name="Head">
        <inertial>
            <origin xyz="-0.10292722677499422 0 0.3917720333837179" rpy="0 0 0"/>
            <mass value="1" />
            <inertia ixx="100" ixy="0" ixz="0" iyy="100" iyz="0" izz="100" />
        </inertial>
        <visual>
            <origin xyz="-0.10292722677499422 0 0.3917720333837179" rpy="0 0 0"/>
            <geometry>
                <box size="0.4117089070999769 0.44938057250415236 0.3917720333837179" />
            </geometry>
            <material name="Blue">
                <color rgba="0.0 0.0 1.0 1.0"/>
            </material>
        </visual>
        <collision>
            <origin xyz="-0.10292722677499422 0 0.3917720333837179" rpy="0 0 0"/>
            <geometry>
                <box size="0.4117089070999769 0.44938057250415236 0.3917720333837179" />
            </geometry>
        </collision>
    </link>
    <joint name="0_2" type="revolute">
       <parent link="0"/>
       <child  link="2"/>
       <origin rpy="0 0 0" xyz="-0.5489452094666358 0.44938057250415236 1.695886016691859" />
     <axis xyz="0 1 0"/>
       <limit effort="0.0" lower="-3.14159" upper="3.14159" velocity="0.0"/>
    </joint>
    <link name="2">
        <inertial>
            <origin xyz="0 0.10748953305586557 -0.45" rpy="0 0 0"/>
            <mass value="1" />
            <inertia ixx="100" ixy="0" ixz="0" iyy="100" iyz="0" izz="100" />
        </inertial>
        <visual>
            <origin xyz="0 0.10748953305586557 -0.45" rpy="0 0 0"/>
            <geometry>
                <box size="0.2869048733881885 0.21497906611173115 0.9" />
            </geometry>
            <material name="Green">
                <color rgba="0 1.0 0.0 1.0"/>
            </material>
        </visual>
        <collision>
            <origin xyz="0 0.10748953305586557 -0.45" rpy="0 0 0"/>
            <geometry>
                <box size="0.2869048733881885 0.21497906611173115 0.9" />
            </geometry>
        </collision>
    </link>
    <joint name="2_12" type="revolute">
       <parent link="2"/>
       <child  link="12"/>
       <origin rpy="0 0 0" xyz="-0.14345243669409424 0.10748953305586557 -0.9" />
     <axis xyz="0 1 0"/>
       <limit effort="0.0" lower="-3.14159" upper="3.14159" velocity="0.0"/>
    </joint>
    <link name="12">
        <inertial>
            <origin xyz="-0.2605359974965415 0 0" rpy="0 0 0"/>
            <mass value="1" />
            <inertia ixx="100" ixy="0" ixz="0" iyy="100" iyz="0" izz="100" />
        </inertial>
        <visual>
            <origin xyz="-0.2605359974965415 0 0" rpy="0 0 0"/>
            <geometry>
                <box size="0.521071994993083 0.21497906611173115 0.1" />
            </geometry>
            <material name="Blue">
                <color rgba="0 0.0 1.0 1.0"/>
            </material>
        </visual>
        <collision>
            <origin xyz="-0.2605359974965415 0 0" rpy="0 0 0"/>
            <geometry>
                <box size="0.521071994993083 0.21497906611173115 0.1" />
            </geometry>
        </collision>
    </link>
</robot>