<robot name = "robot">
    <link name="0">
        <inertial>
            <origin xyz="0 0 1.6824025709969246" rpy="0 0 0"/>
            <mass value="1" />
            <inertia ixx="100" ixy="0" ixz="0" iyy="100" iyz="0" izz="100" />
        </inertial>
        <visual>
            <origin xyz="0 0 1.6824025709969246" rpy="0 0 0"/>
            <geometry>
                <box size="1.7088995036836667 0.7833207621128937 0.3648051419938493" />
            </geometry>
            <material name="Green">
                <color rgba="0 1.0 0.0 1.0"/>
            </material>
        </visual>
        <collision>
            <origin xyz="0 0 1.6824025709969246" rpy="0 0 0"/>
            <geometry>
                <box size="1.7088995036836667 0.7833207621128937 0.3648051419938493" />
            </geometry>
        </collision>
    </link>
    <joint name="0_Head" type="revolute">
       <parent link="0"/>
       <child  link="Head"/>
       <origin rpy="0 0 0" xyz="-0.8544497518418334 0 1.6824025709969246" />
     <axis xyz="0 1 0"/>
       <limit effort="0.0" lower="-3.14159" upper="3.14159" velocity="0.0"/>
    </joint>
    <link name="Head">
        <inertial>
            <origin xyz="-0.10680621898022917 0 0.3648051419938493" rpy="0 0 0"/>
            <mass value="1" />
            <inertia ixx="100" ixy="0" ixz="0" iyy="100" iyz="0" izz="100" />
        </inertial>
        <visual>
            <origin xyz="-0.10680621898022917 0 0.3648051419938493" rpy="0 0 0"/>
            <geometry>
                <box size="0.4272248759209167 0.39166038105644685 0.3648051419938493" />
            </geometry>
            <material name="Blue">
                <color rgba="0.0 0.0 1.0 1.0"/>
            </material>
        </visual>
        <collision>
            <origin xyz="-0.10680621898022917 0 0.3648051419938493" rpy="0 0 0"/>
            <geometry>
                <box size="0.4272248759209167 0.39166038105644685 0.3648051419938493" />
            </geometry>
        </collision>
    </link>
    <joint name="0_1" type="revolute">
       <parent link="0"/>
       <child  link="1"/>
       <origin rpy="0 0 0" xyz="0.5696331678945555 0.39166038105644685 1.6824025709969246" />
     <axis xyz="0 1 0"/>
       <limit effort="0.0" lower="-3.14159" upper="3.14159" velocity="0.0"/>
    </joint>
    <link name="1">
        <inertial>
            <origin xyz="0 0.21610897495209985 -0.45" rpy="0 0 0"/>
            <mass value="1" />
            <inertia ixx="100" ixy="0" ixz="0" iyy="100" iyz="0" izz="100" />
        </inertial>
        <visual>
            <origin xyz="0 0.21610897495209985 -0.45" rpy="0 0 0"/>
            <geometry>
                <box size="0.3298563603322683 0.4322179499041997 0.9" />
            </geometry>
            <material name="Green">
                <color rgba="0 1.0 0.0 1.0"/>
            </material>
        </visual>
        <collision>
            <origin xyz="0 0.21610897495209985 -0.45" rpy="0 0 0"/>
            <geometry>
                <box size="0.3298563603322683 0.4322179499041997 0.9" />
            </geometry>
        </collision>
    </link>
    <joint name="1_11" type="revolute">
       <parent link="1"/>
       <child  link="11"/>
       <origin rpy="0 0 0" xyz="-0.16492818016613414 0.21610897495209985 -0.9" />
     <axis xyz="0 1 0"/>
       <limit effort="0.0" lower="-3.14159" upper="3.14159" velocity="0.0"/>
    </joint>
    <link name="11">
        <inertial>
            <origin xyz="-0.2514840361997435 0 0" rpy="0 0 0"/>
            <mass value="1" />
            <inertia ixx="100" ixy="0" ixz="0" iyy="100" iyz="0" izz="100" />
        </inertial>
        <visual>
            <origin xyz="-0.2514840361997435 0 0" rpy="0 0 0"/>
            <geometry>
                <box size="0.502968072399487 0.4322179499041997 0.1" />
            </geometry>
            <material name="Green">
                <color rgba="0 1.0 0.0 1.0"/>
            </material>
        </visual>
        <collision>
            <origin xyz="-0.2514840361997435 0 0" rpy="0 0 0"/>
            <geometry>
                <box size="0.502968072399487 0.4322179499041997 0.1" />
            </geometry>
        </collision>
    </link>
    <joint name="0_2" type="revolute">
       <parent link="0"/>
       <child  link="2"/>
       <origin rpy="0 0 0" xyz="-0.5696331678945555 0.39166038105644685 1.6824025709969246" />
     <axis xyz="0 1 0"/>
       <limit effort="0.0" lower="-3.14159" upper="3.14159" velocity="0.0"/>
    </joint>
    <link name="2">
        <inertial>
            <origin xyz="0 0.09555056527393464 -0.45" rpy="0 0 0"/>
            <mass value="1" />
            <inertia ixx="100" ixy="0" ixz="0" iyy="100" iyz="0" izz="100" />
        </inertial>
        <visual>
            <origin xyz="0 0.09555056527393464 -0.45" rpy="0 0 0"/>
            <geometry>
                <box size="0.2539947990064919 0.19110113054786929 0.9" />
            </geometry>
            <material name="Blue">
                <color rgba="0 0.0 1.0 1.0"/>
            </material>
        </visual>
        <collision>
            <origin xyz="0 0.09555056527393464 -0.45" rpy="0 0 0"/>
            <geometry>
                <box size="0.2539947990064919 0.19110113054786929 0.9" />
            </geometry>
        </collision>
    </link>
    <joint name="2_12" type="revolute">
       <parent link="2"/>
       <child  link="12"/>
       <origin rpy="0 0 0" xyz="-0.12699739950324596 0.09555056527393464 -0.9" />
     <axis xyz="0 1 0"/>
       <limit effort="0.0" lower="-3.14159" upper="3.14159" velocity="0.0"/>
    </joint>
    <link name="12">
        <inertial>
            <origin xyz="-0.23103463414735304 0 0" rpy="0 0 0"/>
            <mass value="1" />
            <inertia ixx="100" ixy="0" ixz="0" iyy="100" iyz="0" izz="100" />
        </inertial>
        <visual>
            <origin xyz="-0.23103463414735304 0 0" rpy="0 0 0"/>
            <geometry>
                <box size="0.46206926829470607 0.19110113054786929 0.1" />
            </geometry>
            <material name="Green">
                <color rgba="0 1.0 0.0 1.0"/>
            </material>
        </visual>
        <collision>
            <origin xyz="-0.23103463414735304 0 0" rpy="0 0 0"/>
            <geometry>
                <box size="0.46206926829470607 0.19110113054786929 0.1" />
            </geometry>
        </collision>
    </link>
    <joint name="0_3" type="revolute">
       <parent link="0"/>
       <child  link="3"/>
       <origin rpy="0 0 0" xyz="-0.5696331678945555 -0.39166038105644685 1.6824025709969246" />
     <axis xyz="0 1 0"/>
       <limit effort="0.0" lower="-3.14159" upper="3.14159" velocity="0.0"/>
    </joint>
    <link name="3">
        <inertial>
            <origin xyz="0 -0.22968529979067953 -0.45" rpy="0 0 0"/>
            <mass value="1" />
            <inertia ixx="100" ixy="0" ixz="0" iyy="100" iyz="0" izz="100" />
        </inertial>
        <visual>
            <origin xyz="0 -0.22968529979067953 -0.45" rpy="0 0 0"/>
            <geometry>
                <box size="0.2752201789652581 0.45937059958135906 0.9" />
            </geometry>
            <material name="Green">
                <color rgba="0 1.0 0.0 1.0"/>
            </material>
        </visual>
        <collision>
            <origin xyz="0 -0.22968529979067953 -0.45" rpy="0 0 0"/>
            <geometry>
                <box size="0.2752201789652581 0.45937059958135906 0.9" />
            </geometry>
        </collision>
    </link>
    <joint name="3_13" type="revolute">
       <parent link="3"/>
       <child  link="13"/>
       <origin rpy="0 0 0" xyz="-0.13761008948262904 -0.22968529979067953 -0.9" />
     <axis xyz="0 1 0"/>
       <limit effort="0.0" lower="-3.14159" upper="3.14159" velocity="0.0"/>
    </joint>
    <link name="13">
        <inertial>
            <origin xyz="-0.2748770856091937 0 0" rpy="0 0 0"/>
            <mass value="1" />
            <inertia ixx="100" ixy="0" ixz="0" iyy="100" iyz="0" izz="100" />
        </inertial>
        <visual>
            <origin xyz="-0.2748770856091937 0 0" rpy="0 0 0"/>
            <geometry>
                <box size="0.5497541712183874 0.45937059958135906 0.1" />
            </geometry>
            <material name="Green">
                <color rgba="0 1.0 0.0 1.0"/>
            </material>
        </visual>
        <collision>
            <origin xyz="-0.2748770856091937 0 0" rpy="0 0 0"/>
            <geometry>
                <box size="0.5497541712183874 0.45937059958135906 0.1" />
            </geometry>
        </collision>
    </link>
    <joint name="0_4" type="revolute">
       <parent link="0"/>
       <child  link="4"/>
       <origin rpy="0 0 0" xyz="0.5696331678945555 -0.39166038105644685 1.6824025709969246" />
     <axis xyz="0 1 0"/>
       <limit effort="0.0" lower="-3.14159" upper="3.14159" velocity="0.0"/>
    </joint>
    <link name="4">
        <inertial>
            <origin xyz="0 -0.153902554551633 -0.45" rpy="0 0 0"/>
            <mass value="1" />
            <inertia ixx="100" ixy="0" ixz="0" iyy="100" iyz="0" izz="100" />
        </inertial>
        <visual>
            <origin xyz="0 -0.153902554551633 -0.45" rpy="0 0 0"/>
            <geometry>
                <box size="0.41327994140967095 0.307805109103266 0.9" />
            </geometry>
            <material name="Blue">
                <color rgba="0 0.0 1.0 1.0"/>
            </material>
        </visual>
        <collision>
            <origin xyz="0 -0.153902554551633 -0.45" rpy="0 0 0"/>
            <geometry>
                <box size="0.41327994140967095 0.307805109103266 0.9" />
            </geometry>
        </collision>
    </link>
    <joint name="4_14" type="revolute">
       <parent link="4"/>
       <child  link="14"/>
       <origin rpy="0 0 0" xyz="-0.20663997070483547 -0.153902554551633 -0.9" />
     <axis xyz="0 1 0"/>
       <limit effort="0.0" lower="-3.14159" upper="3.14159" velocity="0.0"/>
    </joint>
    <link name="14">
        <inertial>
            <origin xyz="-0.21847902707199207 0 0" rpy="0 0 0"/>
            <mass value="1" />
            <inertia ixx="100" ixy="0" ixz="0" iyy="100" iyz="0" izz="100" />
        </inertial>
        <visual>
            <origin xyz="-0.21847902707199207 0 0" rpy="0 0 0"/>
            <geometry>
                <box size="0.43695805414398414 0.307805109103266 0.1" />
            </geometry>
            <material name="Green">
                <color rgba="0 1.0 0.0 1.0"/>
            </material>
        </visual>
        <collision>
            <origin xyz="-0.21847902707199207 0 0" rpy="0 0 0"/>
            <geometry>
                <box size="0.43695805414398414 0.307805109103266 0.1" />
            </geometry>
        </collision>
    </link>
</robot>