<robot name = "robot">
    <link name="0">
        <inertial>
            <origin xyz="0 0 1.686610811666351" rpy="0 0 0"/>
            <mass value="1" />
            <inertia ixx="100" ixy="0" ixz="0" iyy="100" iyz="0" izz="100" />
        </inertial>
        <visual>
            <origin xyz="0 0 1.686610811666351" rpy="0 0 0"/>
            <geometry>
                <box size="1.5361753299712222 1.4089615043629968 0.37322162333270215" />
            </geometry>
            <material name="Green">
                <color rgba="0 1.0 0.0 1.0"/>
            </material>
        </visual>
        <collision>
            <origin xyz="0 0 1.686610811666351" rpy="0 0 0"/>
            <geometry>
                <box size="1.5361753299712222 1.4089615043629968 0.37322162333270215" />
            </geometry>
        </collision>
    </link>
    <joint name="0_Head" type="revolute">
       <parent link="0"/>
       <child  link="Head"/>
       <origin rpy="0 0 0" xyz="-0.7680876649856111 0 1.686610811666351" />
     <axis xyz="0 1 0"/>
       <limit effort="0.0" lower="-3.14159" upper="3.14159" velocity="0.0"/>
    </joint>
    <link name="Head">
        <inertial>
            <origin xyz="-0.09601095812320139 0 0.37322162333270215" rpy="0 0 0"/>
            <mass value="1" />
            <inertia ixx="100" ixy="0" ixz="0" iyy="100" iyz="0" izz="100" />
        </inertial>
        <visual>
            <origin xyz="-0.09601095812320139 0 0.37322162333270215" rpy="0 0 0"/>
            <geometry>
                <box size="0.38404383249280555 0.7044807521814984 0.37322162333270215" />
            </geometry>
            <material name="Blue">
                <color rgba="0.0 0.0 1.0 1.0"/>
            </material>
        </visual>
        <collision>
            <origin xyz="-0.09601095812320139 0 0.37322162333270215" rpy="0 0 0"/>
            <geometry>
                <box size="0.38404383249280555 0.7044807521814984 0.37322162333270215" />
            </geometry>
        </collision>
    </link>
    <joint name="0_1" type="revolute">
       <parent link="0"/>
       <child  link="1"/>
       <origin rpy="0 0 0" xyz="0.5120584433237407 0.7044807521814984 1.686610811666351" />
     <axis xyz="0 1 0"/>
       <limit effort="0.0" lower="-3.14159" upper="3.14159" velocity="0.0"/>
    </joint>
    <link name="1">
        <inertial>
            <origin xyz="0 0.09203155896568008 -0.6548916674504999" rpy="0 0 0"/>
            <mass value="1" />
            <inertia ixx="100" ixy="0" ixz="0" iyy="100" iyz="0" izz="100" />
        </inertial>
        <visual>
            <origin xyz="0 0.09203155896568008 -0.6548916674504999" rpy="0 0 0"/>
            <geometry>
                <box size="0.15826807772089105 0.18406311793136015 1.3097833349009997" />
            </geometry>
            <material name="Blue">
                <color rgba="0 0.0 1.0 1.0"/>
            </material>
        </visual>
        <collision>
            <origin xyz="0 0.09203155896568008 -0.6548916674504999" rpy="0 0 0"/>
            <geometry>
                <box size="0.15826807772089105 0.18406311793136015 1.3097833349009997" />
            </geometry>
        </collision>
    </link>
    <joint name="1_11" type="revolute">
       <parent link="1"/>
       <child  link="11"/>
       <origin rpy="0 0 0" xyz="-0.07913403886044552 0.09203155896568008 -1.3097833349009997" />
     <axis xyz="0 1 0"/>
       <limit effort="0.0" lower="-3.14159" upper="3.14159" velocity="0.0"/>
    </joint>
    <link name="11">
        <inertial>
            <origin xyz="-0.2728357415300945 0 0" rpy="0 0 0"/>
            <mass value="1" />
            <inertia ixx="100" ixy="0" ixz="0" iyy="100" iyz="0" izz="100" />
        </inertial>
        <visual>
            <origin xyz="-0.2728357415300945 0 0" rpy="0 0 0"/>
            <geometry>
                <box size="0.545671483060189 0.18406311793136015 0.10363283717479756" />
            </geometry>
            <material name="Green">
                <color rgba="0 1.0 0.0 1.0"/>
            </material>
        </visual>
        <collision>
            <origin xyz="-0.2728357415300945 0 0" rpy="0 0 0"/>
            <geometry>
                <box size="0.545671483060189 0.18406311793136015 0.10363283717479756" />
            </geometry>
        </collision>
    </link>
    <joint name="0_2" type="revolute">
       <parent link="0"/>
       <child  link="2"/>
       <origin rpy="0 0 0" xyz="-0.5120584433237407 0.7044807521814984 1.686610811666351" />
     <axis xyz="0 1 0"/>
       <limit effort="0.0" lower="-3.14159" upper="3.14159" velocity="0.0"/>
    </joint>
    <link name="2">
        <inertial>
            <origin xyz="0 0.06545415394723515 -0.6367758404285158" rpy="0 0 0"/>
            <mass value="1" />
            <inertia ixx="100" ixy="0" ixz="0" iyy="100" iyz="0" izz="100" />
        </inertial>
        <visual>
            <origin xyz="0 0.06545415394723515 -0.6367758404285158" rpy="0 0 0"/>
            <geometry>
                <box size="0.48932039523535853 0.1309083078944703 1.2735516808570315" />
            </geometry>
            <material name="Blue">
                <color rgba="0 0.0 1.0 1.0"/>
            </material>
        </visual>
        <collision>
            <origin xyz="0 0.06545415394723515 -0.6367758404285158" rpy="0 0 0"/>
            <geometry>
                <box size="0.48932039523535853 0.1309083078944703 1.2735516808570315" />
            </geometry>
        </collision>
    </link>
    <joint name="2_12" type="revolute">
       <parent link="2"/>
       <child  link="12"/>
       <origin rpy="0 0 0" xyz="-0.24466019761767926 0.06545415394723515 -1.2735516808570315" />
     <axis xyz="0 1 0"/>
       <limit effort="0.0" lower="-3.14159" upper="3.14159" velocity="0.0"/>
    </joint>
    <link name="12">
        <inertial>
            <origin xyz="-0.3107001716648183 0 0" rpy="0 0 0"/>
            <mass value="1" />
            <inertia ixx="100" ixy="0" ixz="0" iyy="100" iyz="0" izz="100" />
        </inertial>
        <visual>
            <origin xyz="-0.3107001716648183 0 0" rpy="0 0 0"/>
            <geometry>
                <box size="0.6214003433296366 0.1309083078944703 0.12176704477004871" />
            </geometry>
            <material name="Blue">
                <color rgba="0 0.0 1.0 1.0"/>
            </material>
        </visual>
        <collision>
            <origin xyz="-0.3107001716648183 0 0" rpy="0 0 0"/>
            <geometry>
                <box size="0.6214003433296366 0.1309083078944703 0.12176704477004871" />
            </geometry>
        </collision>
    </link>
    <joint name="0_3" type="revolute">
       <parent link="0"/>
       <child  link="3"/>
       <origin rpy="0 0 0" xyz="-0.5120584433237407 -0.7044807521814984 1.686610811666351" />
     <axis xyz="0 1 0"/>
       <limit effort="0.0" lower="-3.14159" upper="3.14159" velocity="0.0"/>
    </joint>
    <link name="3">
        <inertial>
            <origin xyz="0 -0.20994112283085364 -0.5018799920788646" rpy="0 0 0"/>
            <mass value="1" />
            <inertia ixx="100" ixy="0" ixz="0" iyy="100" iyz="0" izz="100" />
        </inertial>
        <visual>
            <origin xyz="0 -0.20994112283085364 -0.5018799920788646" rpy="0 0 0"/>
            <geometry>
                <box size="0.42783446506809075 0.4198822456617073 1.0037599841577292" />
            </geometry>
            <material name="Blue">
                <color rgba="0 0.0 1.0 1.0"/>
            </material>
        </visual>
        <collision>
            <origin xyz="0 -0.20994112283085364 -0.5018799920788646" rpy="0 0 0"/>
            <geometry>
                <box size="0.42783446506809075 0.4198822456617073 1.0037599841577292" />
            </geometry>
        </collision>
    </link>
    <joint name="3_13" type="revolute">
       <parent link="3"/>
       <child  link="13"/>
       <origin rpy="0 0 0" xyz="-0.21391723253404538 -0.20994112283085364 -1.0037599841577292" />
     <axis xyz="0 1 0"/>
       <limit effort="0.0" lower="-3.14159" upper="3.14159" velocity="0.0"/>
    </joint>
    <link name="13">
        <inertial>
            <origin xyz="-0.33951512466481104 0 0" rpy="0 0 0"/>
            <mass value="1" />
            <inertia ixx="100" ixy="0" ixz="0" iyy="100" iyz="0" izz="100" />
        </inertial>
        <visual>
            <origin xyz="-0.33951512466481104 0 0" rpy="0 0 0"/>
            <geometry>
                <box size="0.6790302493296221 0.4198822456617073 0.13176310294773727" />
            </geometry>
            <material name="Blue">
                <color rgba="0 0.0 1.0 1.0"/>
            </material>
        </visual>
        <collision>
            <origin xyz="-0.33951512466481104 0 0" rpy="0 0 0"/>
            <geometry>
                <box size="0.6790302493296221 0.4198822456617073 0.13176310294773727" />
            </geometry>
        </collision>
    </link>
    <joint name="0_4" type="revolute">
       <parent link="0"/>
       <child  link="4"/>
       <origin rpy="0 0 0" xyz="0.5120584433237407 -0.7044807521814984 1.686610811666351" />
     <axis xyz="0 1 0"/>
       <limit effort="0.0" lower="-3.14159" upper="3.14159" velocity="0.0"/>
    </joint>
    <link name="4">
        <inertial>
            <origin xyz="0 -0.158568006890572 -0.5135135626639438" rpy="0 0 0"/>
            <mass value="1" />
            <inertia ixx="100" ixy="0" ixz="0" iyy="100" iyz="0" izz="100" />
        </inertial>
        <visual>
            <origin xyz="0 -0.158568006890572 -0.5135135626639438" rpy="0 0 0"/>
            <geometry>
                <box size="0.30650295855446597 0.317136013781144 1.0270271253278875" />
            </geometry>
            <material name="Blue">
                <color rgba="0 0.0 1.0 1.0"/>
            </material>
        </visual>
        <collision>
            <origin xyz="0 -0.158568006890572 -0.5135135626639438" rpy="0 0 0"/>
            <geometry>
                <box size="0.30650295855446597 0.317136013781144 1.0270271253278875" />
            </geometry>
        </collision>
    </link>
    <joint name="4_14" type="revolute">
       <parent link="4"/>
       <child  link="14"/>
       <origin rpy="0 0 0" xyz="-0.15325147927723298 -0.158568006890572 -1.0270271253278875" />
     <axis xyz="0 1 0"/>
       <limit effort="0.0" lower="-3.14159" upper="3.14159" velocity="0.0"/>
    </joint>
    <link name="14">
        <inertial>
            <origin xyz="-0.28031057408820276 0 0" rpy="0 0 0"/>
            <mass value="1" />
            <inertia ixx="100" ixy="0" ixz="0" iyy="100" iyz="0" izz="100" />
        </inertial>
        <visual>
            <origin xyz="-0.28031057408820276 0 0" rpy="0 0 0"/>
            <geometry>
                <box size="0.5606211481764055 0.317136013781144 0.13033157447547855" />
            </geometry>
            <material name="Green">
                <color rgba="0 1.0 0.0 1.0"/>
            </material>
        </visual>
        <collision>
            <origin xyz="-0.28031057408820276 0 0" rpy="0 0 0"/>
            <geometry>
                <box size="0.5606211481764055 0.317136013781144 0.13033157447547855" />
            </geometry>
        </collision>
    </link>
</robot>