<robot name = "robot">
    <link name="0">
        <inertial>
            <origin xyz="0 0 0.11585985073131053" rpy="0 0 0"/>
            <mass value="1" />
            <inertia ixx="100" ixy="0" ixz="0" iyy="100" iyz="0" izz="100" />
        </inertial>
        <visual>
            <origin xyz="0 0 0.11585985073131053" rpy="0 0 0"/>
            <geometry>
                <box size="1.808077213006712 0.5508372319311375 0.23171970146262105" />
            </geometry>
            <material name="Green">
                <color rgba="0 1.0 0.0 1.0"/>
            </material>
        </visual>
        <collision>
            <origin xyz="0 0 0.11585985073131053" rpy="0 0 0"/>
            <geometry>
                <box size="1.808077213006712 0.5508372319311375 0.23171970146262105" />
            </geometry>
        </collision>
    </link>
    <joint name="0_Head" type="revolute">
       <parent link="0"/>
       <child  link="Head"/>
       <origin rpy="0 0 0" xyz="-0.904038606503356 0 0.11585985073131053" />
     <axis xyz="0 1 0"/>
       <limit effort="0.0" lower="-3.14159" upper="3.14159" velocity="0.0"/>
    </joint>
    <link name="Head">
        <inertial>
            <origin xyz="-0.1130048258129195 0 0.17378977609696578" rpy="0 0 0"/>
            <mass value="1" />
            <inertia ixx="100" ixy="0" ixz="0" iyy="100" iyz="0" izz="100" />
        </inertial>
        <visual>
            <origin xyz="-0.1130048258129195 0 0.17378977609696578" rpy="0 0 0"/>
            <geometry>
                <box size="0.452019303251678 0.27541861596556877 0.17378977609696578" />
            </geometry>
            <material name="Cyan">
                <color rgba="0.0 1.0 1.0 1.0"/>
            </material>
        </visual>
        <collision>
            <origin xyz="-0.1130048258129195 0 0.17378977609696578" rpy="0 0 0"/>
            <geometry>
                <box size="0.452019303251678 0.27541861596556877 0.17378977609696578" />
            </geometry>
        </collision>
    </link>
    <joint name="0_3" type="revolute">
       <parent link="0"/>
       <child  link="3"/>
       <origin rpy="0 0 0" xyz="-0.6026924043355707 -0.27541861596556877 0.11585985073131053" />
     <axis xyz="1 0 0"/>
       <limit effort="0.0" lower="-3.14159" upper="3.14159" velocity="0.0"/>
    </joint>
    <link name="3">
        <inertial>
            <origin xyz="-0.18234994323919917 -0.3029362222266356 -0.05814029940443264" rpy="0 0 0"/>
            <mass value="1" />
            <inertia ixx="100" ixy="0" ixz="0" iyy="100" iyz="0" izz="100" />
        </inertial>
        <visual>
            <origin xyz="-0.18234994323919917 -0.3029362222266356 -0.05814029940443264" rpy="0 0 0"/>
            <geometry>
                <box size="0.36469988647839835 0.6058724444532712 0.11628059880886528" />
            </geometry>
            <material name="Blue">
                <color rgba="0 0.0 1.0 1.0"/>
            </material>
        </visual>
        <collision>
            <origin xyz="-0.18234994323919917 -0.3029362222266356 -0.05814029940443264" rpy="0 0 0"/>
            <geometry>
                <box size="0.36469988647839835 0.6058724444532712 0.11628059880886528" />
            </geometry>
        </collision>
    </link>
    <joint name="3_13" type="revolute">
       <parent link="3"/>
       <child  link="13"/>
       <origin rpy="0 0 0" xyz="0 -0.6058724444532712 -0.05814029940443264" />
     <axis xyz="0 1 0"/>
       <limit effort="0.0" lower="-3.14159" upper="3.14159" velocity="0.0"/>
    </joint>
    <link name="13">
        <inertial>
            <origin xyz="0.4047194469549764 0.09265585671587301 -0.1" rpy="0 0 0"/>
            <mass value="1" />
            <inertia ixx="100" ixy="0" ixz="0" iyy="100" iyz="0" izz="100" />
        </inertial>
        <visual>
            <origin xyz="0.4047194469549764 0.09265585671587301 -0.1" rpy="0 0 0"/>
            <geometry>
                <box size="0.8094388939099528 0.18531171343174602 0.2" />
            </geometry>
            <material name="Blue">
                <color rgba="0 0.0 1.0 1.0"/>
            </material>
        </visual>
        <collision>
            <origin xyz="0.4047194469549764 0.09265585671587301 -0.1" rpy="0 0 0"/>
            <geometry>
                <box size="0.8094388939099528 0.18531171343174602 0.2" />
            </geometry>
        </collision>
    </link>
    <joint name="0_4" type="revolute">
       <parent link="0"/>
       <child  link="4"/>
       <origin rpy="0 0 0" xyz="0.6026924043355707 -0.27541861596556877 0.11585985073131053" />
     <axis xyz="1 0 0"/>
       <limit effort="0.0" lower="-3.14159" upper="3.14159" velocity="0.0"/>
    </joint>
    <link name="4">
        <inertial>
            <origin xyz="0.236732363675699 -0.3126962953377866 -0.06402390964673174" rpy="0 0 0"/>
            <mass value="1" />
            <inertia ixx="100" ixy="0" ixz="0" iyy="100" iyz="0" izz="100" />
        </inertial>
        <visual>
            <origin xyz="0.236732363675699 -0.3126962953377866 -0.06402390964673174" rpy="0 0 0"/>
            <geometry>
                <box size="0.473464727351398 0.6253925906755732 0.12804781929346348" />
            </geometry>
            <material name="Blue">
                <color rgba="0 0.0 1.0 1.0"/>
            </material>
        </visual>
        <collision>
            <origin xyz="0.236732363675699 -0.3126962953377866 -0.06402390964673174" rpy="0 0 0"/>
            <geometry>
                <box size="0.473464727351398 0.6253925906755732 0.12804781929346348" />
            </geometry>
        </collision>
    </link>
</robot>