<robot name = "robot">
    <link name="0">
        <inertial>
            <origin xyz="0 0 1.637549387204352" rpy="0 0 0"/>
            <mass value="1" />
            <inertia ixx="100" ixy="0" ixz="0" iyy="100" iyz="0" izz="100" />
        </inertial>
        <visual>
            <origin xyz="0 0 1.637549387204352" rpy="0 0 0"/>
            <geometry>
                <box size="1.6553195896802329 1.3041586720563596 0.27509877440870434" />
            </geometry>
            <material name="Blue">
                <color rgba="0 0.0 1.0 1.0"/>
            </material>
        </visual>
        <collision>
            <origin xyz="0 0 1.637549387204352" rpy="0 0 0"/>
            <geometry>
                <box size="1.6553195896802329 1.3041586720563596 0.27509877440870434" />
            </geometry>
        </collision>
    </link>
    <joint name="0_Head" type="revolute">
       <parent link="0"/>
       <child  link="Head"/>
       <origin rpy="0 0 0" xyz="-0.8276597948401164 0 1.637549387204352" />
     <axis xyz="0 1 0"/>
       <limit effort="0.0" lower="-3.14159" upper="3.14159" velocity="0.0"/>
    </joint>
    <link name="Head">
        <inertial>
            <origin xyz="-0.10345747435501455 0 0.27509877440870434" rpy="0 0 0"/>
            <mass value="1" />
            <inertia ixx="100" ixy="0" ixz="0" iyy="100" iyz="0" izz="100" />
        </inertial>
        <visual>
            <origin xyz="-0.10345747435501455 0 0.27509877440870434" rpy="0 0 0"/>
            <geometry>
                <box size="0.4138298974200582 0.6520793360281798 0.27509877440870434" />
            </geometry>
            <material name="Blue">
                <color rgba="0.0 0.0 1.0 1.0"/>
            </material>
        </visual>
        <collision>
            <origin xyz="-0.10345747435501455 0 0.27509877440870434" rpy="0 0 0"/>
            <geometry>
                <box size="0.4138298974200582 0.6520793360281798 0.27509877440870434" />
            </geometry>
        </collision>
    </link>
    <joint name="0_1" type="revolute">
       <parent link="0"/>
       <child  link="1"/>
       <origin rpy="0 0 0" xyz="0.5517731965600776 0.6520793360281798 1.637549387204352" />
     <axis xyz="0 1 0"/>
       <limit effort="0.0" lower="-3.14159" upper="3.14159" velocity="0.0"/>
    </joint>
    <link name="1">
        <inertial>
            <origin xyz="0 0.06424188070089801 -0.45" rpy="0 0 0"/>
            <mass value="1" />
            <inertia ixx="100" ixy="0" ixz="0" iyy="100" iyz="0" izz="100" />
        </inertial>
        <visual>
            <origin xyz="0 0.06424188070089801 -0.45" rpy="0 0 0"/>
            <geometry>
                <box size="0.3117724507662778 0.12848376140179602 0.9" />
            </geometry>
            <material name="Green">
                <color rgba="0 1.0 0.0 1.0"/>
            </material>
        </visual>
        <collision>
            <origin xyz="0 0.06424188070089801 -0.45" rpy="0 0 0"/>
            <geometry>
                <box size="0.3117724507662778 0.12848376140179602 0.9" />
            </geometry>
        </collision>
    </link>
    <joint name="1_11" type="revolute">
       <parent link="1"/>
       <child  link="11"/>
       <origin rpy="0 0 0" xyz="-0.1558862253831389 0.06424188070089801 -0.9" />
     <axis xyz="0 1 0"/>
       <limit effort="0.0" lower="-3.14159" upper="3.14159" velocity="0.0"/>
    </joint>
    <link name="11">
        <inertial>
            <origin xyz="-0.2631577206419582 0 0" rpy="0 0 0"/>
            <mass value="1" />
            <inertia ixx="100" ixy="0" ixz="0" iyy="100" iyz="0" izz="100" />
        </inertial>
        <visual>
            <origin xyz="-0.2631577206419582 0 0" rpy="0 0 0"/>
            <geometry>
                <box size="0.5263154412839164 0.12848376140179602 0.1" />
            </geometry>
            <material name="Blue">
                <color rgba="0 0.0 1.0 1.0"/>
            </material>
        </visual>
        <collision>
            <origin xyz="-0.2631577206419582 0 0" rpy="0 0 0"/>
            <geometry>
                <box size="0.5263154412839164 0.12848376140179602 0.1" />
            </geometry>
        </collision>
    </link>
    <joint name="0_3" type="revolute">
       <parent link="0"/>
       <child  link="3"/>
       <origin rpy="0 0 0" xyz="-0.5517731965600776 -0.6520793360281798 1.637549387204352" />
     <axis xyz="0 1 0"/>
       <limit effort="0.0" lower="-3.14159" upper="3.14159" velocity="0.0"/>
    </joint>
    <link name="3">
        <inertial>
            <origin xyz="0 -0.1579436688422478 -0.45" rpy="0 0 0"/>
            <mass value="1" />
            <inertia ixx="100" ixy="0" ixz="0" iyy="100" iyz="0" izz="100" />
        </inertial>
        <visual>
            <origin xyz="0 -0.1579436688422478 -0.45" rpy="0 0 0"/>
            <geometry>
                <box size="0.29482473845851576 0.3158873376844956 0.9" />
            </geometry>
            <material name="Green">
                <color rgba="0 1.0 0.0 1.0"/>
            </material>
        </visual>
        <collision>
            <origin xyz="0 -0.1579436688422478 -0.45" rpy="0 0 0"/>
            <geometry>
                <box size="0.29482473845851576 0.3158873376844956 0.9" />
            </geometry>
        </collision>
    </link>
    <joint name="3_13" type="revolute">
       <parent link="3"/>
       <child  link="13"/>
       <origin rpy="0 0 0" xyz="-0.14741236922925788 -0.1579436688422478 -0.9" />
     <axis xyz="0 1 0"/>
       <limit effort="0.0" lower="-3.14159" upper="3.14159" velocity="0.0"/>
    </joint>
    <link name="13">
        <inertial>
            <origin xyz="-0.2904774543751705 0 0" rpy="0 0 0"/>
            <mass value="1" />
            <inertia ixx="100" ixy="0" ixz="0" iyy="100" iyz="0" izz="100" />
        </inertial>
        <visual>
            <origin xyz="-0.2904774543751705 0 0" rpy="0 0 0"/>
            <geometry>
                <box size="0.580954908750341 0.3158873376844956 0.1" />
            </geometry>
            <material name="Green">
                <color rgba="0 1.0 0.0 1.0"/>
            </material>
        </visual>
        <collision>
            <origin xyz="-0.2904774543751705 0 0" rpy="0 0 0"/>
            <geometry>
                <box size="0.580954908750341 0.3158873376844956 0.1" />
            </geometry>
        </collision>
    </link>
    <joint name="0_4" type="revolute">
       <parent link="0"/>
       <child  link="4"/>
       <origin rpy="0 0 0" xyz="0.5517731965600776 -0.6520793360281798 1.637549387204352" />
     <axis xyz="0 1 0"/>
       <limit effort="0.0" lower="-3.14159" upper="3.14159" velocity="0.0"/>
    </joint>
    <link name="4">
        <inertial>
            <origin xyz="0 -0.20209567810307755 -0.45" rpy="0 0 0"/>
            <mass value="1" />
            <inertia ixx="100" ixy="0" ixz="0" iyy="100" iyz="0" izz="100" />
        </inertial>
        <visual>
            <origin xyz="0 -0.20209567810307755 -0.45" rpy="0 0 0"/>
            <geometry>
                <box size="0.3136321000469312 0.4041913562061551 0.9" />
            </geometry>
            <material name="Green">
                <color rgba="0 1.0 0.0 1.0"/>
            </material>
        </visual>
        <collision>
            <origin xyz="0 -0.20209567810307755 -0.45" rpy="0 0 0"/>
            <geometry>
                <box size="0.3136321000469312 0.4041913562061551 0.9" />
            </geometry>
        </collision>
    </link>
</robot>