<robot name = "robot">
    <link name="0">
        <inertial>
            <origin xyz="0 0 0.9113847504925268" rpy="0 0 0"/>
            <mass value="1" />
            <inertia ixx="100" ixy="0" ixz="0" iyy="100" iyz="0" izz="100" />
        </inertial>
        <visual>
            <origin xyz="0 0 0.9113847504925268" rpy="0 0 0"/>
            <geometry>
                <box size="1.5299371107444248 1.2737753409324566 0.2227695009850535" />
            </geometry>
            <material name="Blue">
                <color rgba="0.0 0.0 1.0 1.0"/>
            </material>
        </visual>
        <collision>
            <origin xyz="0 0 0.9113847504925268" rpy="0 0 0"/>
            <geometry>
                <box size="1.5299371107444248 1.2737753409324566 0.2227695009850535" />
            </geometry>
        </collision>
    </link>
    <joint name="0_Head" type="revolute">
       <parent link="0"/>
       <child  link="Head"/>
       <origin rpy="0 0 0" xyz="-0.7649685553722124 0 0.9113847504925268" />
     <axis xyz="0 1 0"/>
       <limit effort="0.0" lower="-3.14159" upper="3.14159" velocity="0.0"/>
    </joint>
    <link name="Head">
        <inertial>
            <origin xyz="-0.09562106942152655 0 0.2227695009850535" rpy="0 0 0"/>
            <mass value="1" />
            <inertia ixx="100" ixy="0" ixz="0" iyy="100" iyz="0" izz="100" />
        </inertial>
        <visual>
            <origin xyz="-0.09562106942152655 0 0.2227695009850535" rpy="0 0 0"/>
            <geometry>
                <box size="0.3824842776861062 0.6368876704662283 0.2227695009850535" />
            </geometry>
            <material name="Blue">
                <color rgba="0.0 0.0 1.0 1.0"/>
            </material>
        </visual>
        <collision>
            <origin xyz="-0.09562106942152655 0 0.2227695009850535" rpy="0 0 0"/>
            <geometry>
                <box size="0.3824842776861062 0.6368876704662283 0.2227695009850535" />
            </geometry>
        </collision>
    </link>
</robot>