<robot name = "robot">
    <link name="0">
        <inertial>
            <origin xyz="0 0 1.0470649526133289" rpy="0 0 0"/>
            <mass value="1" />
            <inertia ixx="100" ixy="0" ixz="0" iyy="100" iyz="0" izz="100" />
        </inertial>
        <visual>
            <origin xyz="0 0 1.0470649526133289" rpy="0 0 0"/>
            <geometry>
                <box size="1.6559841419614447 0.8405962108887822 0.4941299052266576" />
            </geometry>
            <material name="Blue">
                <color rgba="0.0 0.0 1.0 1.0"/>
            </material>
        </visual>
        <collision>
            <origin xyz="0 0 1.0470649526133289" rpy="0 0 0"/>
            <geometry>
                <box size="1.6559841419614447 0.8405962108887822 0.4941299052266576" />
            </geometry>
        </collision>
    </link>
    <joint name="0_Head" type="revolute">
       <parent link="0"/>
       <child  link="Head"/>
       <origin rpy="0 0 0" xyz="-0.8279920709807224 0 1.0470649526133289" />
     <axis xyz="0 1 0"/>
       <limit effort="0.0" lower="-3.14159" upper="3.14159" velocity="0.0"/>
    </joint>
    <link name="Head">
        <inertial>
            <origin xyz="-0.1034990088725903 0 0.4941299052266576" rpy="0 0 0"/>
            <mass value="1" />
            <inertia ixx="100" ixy="0" ixz="0" iyy="100" iyz="0" izz="100" />
        </inertial>
        <visual>
            <origin xyz="-0.1034990088725903 0 0.4941299052266576" rpy="0 0 0"/>
            <geometry>
                <box size="0.4139960354903612 0.4202981054443911 0.4941299052266576" />
            </geometry>
            <material name="Blue">
                <color rgba="0.0 0.0 1.0 1.0"/>
            </material>
        </visual>
        <collision>
            <origin xyz="-0.1034990088725903 0 0.4941299052266576" rpy="0 0 0"/>
            <geometry>
                <box size="0.4139960354903612 0.4202981054443911 0.4941299052266576" />
            </geometry>
        </collision>
    </link>
    <joint name="0_1" type="revolute">
       <parent link="0"/>
       <child  link="1"/>
       <origin rpy="0 0 0" xyz="0.5519947139871483 0.4202981054443911 1.0470649526133289" />
     <axis xyz="0 1 0"/>
       <limit effort="0.0" lower="-3.14159" upper="3.14159" velocity="0.0"/>
    </joint>
    <link name="1">
        <inertial>
            <origin xyz="0 0.05144412744637908 -0.45" rpy="0 0 0"/>
            <mass value="1" />
            <inertia ixx="100" ixy="0" ixz="0" iyy="100" iyz="0" izz="100" />
        </inertial>
        <visual>
            <origin xyz="0 0.05144412744637908 -0.45" rpy="0 0 0"/>
            <geometry>
                <box size="0.2753573675087658 0.10288825489275816 0.9" />
            </geometry>
            <material name="G">
                <color rgba="0 1.0 0.0 1.0"/>
            </material>
        </visual>
        <collision>
            <origin xyz="0 0.05144412744637908 -0.45" rpy="0 0 0"/>
            <geometry>
                <box size="0.2753573675087658 0.10288825489275816 0.9" />
            </geometry>
        </collision>
    </link>
    <joint name="0_2" type="revolute">
       <parent link="0"/>
       <child  link="2"/>
       <origin rpy="0 0 0" xyz="-0.5519947139871483 0.4202981054443911 1.0470649526133289" />
     <axis xyz="0 1 0"/>
       <limit effort="0.0" lower="-3.14159" upper="3.14159" velocity="0.0"/>
    </joint>
    <link name="2">
        <inertial>
            <origin xyz="0 0.10738355520019478 -0.45" rpy="0 0 0"/>
            <mass value="1" />
            <inertia ixx="100" ixy="0" ixz="0" iyy="100" iyz="0" izz="100" />
        </inertial>
        <visual>
            <origin xyz="0 0.10738355520019478 -0.45" rpy="0 0 0"/>
            <geometry>
                <box size="0.11712045839660457 0.21476711040038957 0.9" />
            </geometry>
            <material name="G">
                <color rgba="0 1.0 0.0 1.0"/>
            </material>
        </visual>
        <collision>
            <origin xyz="0 0.10738355520019478 -0.45" rpy="0 0 0"/>
            <geometry>
                <box size="0.11712045839660457 0.21476711040038957 0.9" />
            </geometry>
        </collision>
    </link>
    <joint name="2_12" type="revolute">
       <parent link="2"/>
       <child  link="12"/>
       <origin rpy="0 0 0" xyz="-0.05856022919830228 0.10738355520019478 -0.9" />
     <axis xyz="0 1 0"/>
       <limit effort="0.0" lower="-3.14159" upper="3.14159" velocity="0.0"/>
    </joint>
    <link name="12">
        <inertial>
            <origin xyz="-0.2014700228755691 0 0" rpy="0 0 0"/>
            <mass value="1" />
            <inertia ixx="100" ixy="0" ixz="0" iyy="100" iyz="0" izz="100" />
        </inertial>
        <visual>
            <origin xyz="-0.2014700228755691 0 0" rpy="0 0 0"/>
            <geometry>
                <box size="0.4029400457511382 0.21476711040038957 0.1" />
            </geometry>
            <material name="G">
                <color rgba="0 1.0 0.0 1.0"/>
            </material>
        </visual>
        <collision>
            <origin xyz="-0.2014700228755691 0 0" rpy="0 0 0"/>
            <geometry>
                <box size="0.4029400457511382 0.21476711040038957 0.1" />
            </geometry>
        </collision>
    </link>
    <joint name="0_3" type="revolute">
       <parent link="0"/>
       <child  link="3"/>
       <origin rpy="0 0 0" xyz="-0.5519947139871483 -0.4202981054443911 1.0470649526133289" />
     <axis xyz="0 1 0"/>
       <limit effort="0.0" lower="-3.14159" upper="3.14159" velocity="0.0"/>
    </joint>
    <link name="3">
        <inertial>
            <origin xyz="0 -0.06357542707545712 -0.45" rpy="0 0 0"/>
            <mass value="1" />
            <inertia ixx="100" ixy="0" ixz="0" iyy="100" iyz="0" izz="100" />
        </inertial>
        <visual>
            <origin xyz="0 -0.06357542707545712 -0.45" rpy="0 0 0"/>
            <geometry>
                <box size="0.3082534717207156 0.12715085415091423 0.9" />
            </geometry>
            <material name="B">
                <color rgba="0 1.0 0.0 1.0"/>
            </material>
        </visual>
        <collision>
            <origin xyz="0 -0.06357542707545712 -0.45" rpy="0 0 0"/>
            <geometry>
                <box size="0.3082534717207156 0.12715085415091423 0.9" />
            </geometry>
        </collision>
    </link>
    <joint name="0_4" type="revolute">
       <parent link="0"/>
       <child  link="4"/>
       <origin rpy="0 0 0" xyz="0.5519947139871483 -0.4202981054443911 1.0470649526133289" />
     <axis xyz="0 1 0"/>
       <limit effort="0.0" lower="-3.14159" upper="3.14159" velocity="0.0"/>
    </joint>
    <link name="4">
        <inertial>
            <origin xyz="0 -0.0857231736818986 -0.45" rpy="0 0 0"/>
            <mass value="1" />
            <inertia ixx="100" ixy="0" ixz="0" iyy="100" iyz="0" izz="100" />
        </inertial>
        <visual>
            <origin xyz="0 -0.0857231736818986 -0.45" rpy="0 0 0"/>
            <geometry>
                <box size="0.34212413348550796 0.1714463473637972 0.9" />
            </geometry>
            <material name="G">
                <color rgba="0 1.0 0.0 1.0"/>
            </material>
        </visual>
        <collision>
            <origin xyz="0 -0.0857231736818986 -0.45" rpy="0 0 0"/>
            <geometry>
                <box size="0.34212413348550796 0.1714463473637972 0.9" />
            </geometry>
        </collision>
    </link>
    <joint name="4_14" type="revolute">
       <parent link="4"/>
       <child  link="14"/>
       <origin rpy="0 0 0" xyz="-0.17106206674275398 -0.0857231736818986 -0.9" />
     <axis xyz="0 1 0"/>
       <limit effort="0.0" lower="-3.14159" upper="3.14159" velocity="0.0"/>
    </joint>
    <link name="14">
        <inertial>
            <origin xyz="-0.25154559490179135 0 0" rpy="0 0 0"/>
            <mass value="1" />
            <inertia ixx="100" ixy="0" ixz="0" iyy="100" iyz="0" izz="100" />
        </inertial>
        <visual>
            <origin xyz="-0.25154559490179135 0 0" rpy="0 0 0"/>
            <geometry>
                <box size="0.5030911898035827 0.1714463473637972 0.1" />
            </geometry>
            <material name="B">
                <color rgba="0 1.0 0.0 1.0"/>
            </material>
        </visual>
        <collision>
            <origin xyz="-0.25154559490179135 0 0" rpy="0 0 0"/>
            <geometry>
                <box size="0.5030911898035827 0.1714463473637972 0.1" />
            </geometry>
        </collision>
    </link>
</robot>